[04:033656] Watching for file changes with StatReloader
[04:033703] Watching for file changes with StatReloader
[04:033711] "POST /ajax/character/svg2pdf/_martin_merkel/ HTTP/1.1" 200 16
[04:033716] "POST /ajax/character/save2svg/_martin_merkel/ HTTP/1.1" 200 16
[04:033729] "POST /ajax/character/svg2pdf/_martin_merkel/ HTTP/1.1" 200 16
[04:033827] "POST /ajax/character/svg2pdf/_martin_merkel/ HTTP/1.1" 200 16
[04:033833] "POST /ajax/character/svg2pdf/_martin_merkel/ HTTP/1.1" 200 16
[04:033837] "POST /ajax/character/svg2pdf/_martin_merkel/ HTTP/1.1" 200 16
[04:033933] /home/zaffarelli/Perso/github/wawwod/wawwod/settings.py changed, reloading.
[04/06 03:39:34] Watching for file changes with StatReloader
[04/06 03:44:14] /home/zaffarelli/Perso/github/wawwod/wawwod/settings.py changed, reloading.
[04/06 03:56:03] "GET /static/storytelling/fonts/Lato-Regular.ttf HTTP/1.1" 404 1861
[04/06 04:00:13] "GET /static/storytelling/fonts/Lato-Regular.ttf HTTP/1.1" 404 1861
[04/06 04:07:13] "GET /static/storytelling/fonts/Lato-Regular.ttf HTTP/1.1" 404 1861
[04/06 04:21:01] "GET /static/storytelling/fonts/Lato-Regular.ttf HTTP/1.1" 404 1861
[04/06 05:29:41] "GET /static/storytelling/fonts/Lato-Regular.ttf HTTP/1.1" 404 1861
[04/06 12:45:44] "GET /static/storytelling/fonts/Lato-Regular.ttf HTTP/1.1" 404 1861
[04/06 13:35:17] Internal Server Error: /admin/storytelling/hotspot/
Traceback (most recent call last):
  File "/home/zaffarelli/.virtualenvs/owod/lib/python3.11/site-packages/django/db/backends/utils.py", line 89, in _execute
    return self.cursor.execute(sql, params)
           ^^^^^^^^^^^^^^^^^^^^^^^^^^^^^^^^
  File "/home/zaffarelli/.virtualenvs/owod/lib/python3.11/site-packages/django/db/backends/mysql/base.py", line 75, in execute
    return self.cursor.execute(query, args)
           ^^^^^^^^^^^^^^^^^^^^^^^^^^^^^^^^
  File "/home/zaffarelli/.virtualenvs/owod/lib64/python3.11/site-packages/MySQLdb/cursors.py", line 206, in execute
    res = self._query(query)
          ^^^^^^^^^^^^^^^^^^
  File "/home/zaffarelli/.virtualenvs/owod/lib64/python3.11/site-packages/MySQLdb/cursors.py", line 319, in _query
    db.query(q)
  File "/home/zaffarelli/.virtualenvs/owod/lib64/python3.11/site-packages/MySQLdb/connections.py", line 254, in query
    _mysql.connection.query(self, query)
MySQLdb.OperationalError: (1054, "Unknown column 'storytelling_hotspot.city_id' in 'field list'")

The above exception was the direct cause of the following exception:

Traceback (most recent call last):
  File "/home/zaffarelli/.virtualenvs/owod/lib/python3.11/site-packages/django/core/handlers/exception.py", line 55, in inner
    response = get_response(request)
               ^^^^^^^^^^^^^^^^^^^^^
  File "/home/zaffarelli/.virtualenvs/owod/lib/python3.11/site-packages/django/core/handlers/base.py", line 197, in _get_response
    response = wrapped_callback(request, *callback_args, **callback_kwargs)
               ^^^^^^^^^^^^^^^^^^^^^^^^^^^^^^^^^^^^^^^^^^^^^^^^^^^^^^^^^^^^
  File "/home/zaffarelli/.virtualenvs/owod/lib/python3.11/site-packages/django/contrib/admin/options.py", line 688, in wrapper
    return self.admin_site.admin_view(view)(*args, **kwargs)
           ^^^^^^^^^^^^^^^^^^^^^^^^^^^^^^^^^^^^^^^^^^^^^^^^^
  File "/home/zaffarelli/.virtualenvs/owod/lib/python3.11/site-packages/django/utils/decorators.py", line 134, in _wrapper_view
    response = view_func(request, *args, **kwargs)
               ^^^^^^^^^^^^^^^^^^^^^^^^^^^^^^^^^^^
  File "/home/zaffarelli/.virtualenvs/owod/lib/python3.11/site-packages/django/views/decorators/cache.py", line 62, in _wrapper_view_func
    response = view_func(request, *args, **kwargs)
               ^^^^^^^^^^^^^^^^^^^^^^^^^^^^^^^^^^^
  File "/home/zaffarelli/.virtualenvs/owod/lib/python3.11/site-packages/django/contrib/admin/sites.py", line 242, in inner
    return view(request, *args, **kwargs)
           ^^^^^^^^^^^^^^^^^^^^^^^^^^^^^^
  File "/home/zaffarelli/.virtualenvs/owod/lib/python3.11/site-packages/django/utils/decorators.py", line 46, in _wrapper
    return bound_method(*args, **kwargs)
           ^^^^^^^^^^^^^^^^^^^^^^^^^^^^^
  File "/home/zaffarelli/.virtualenvs/owod/lib/python3.11/site-packages/django/utils/decorators.py", line 134, in _wrapper_view
    response = view_func(request, *args, **kwargs)
               ^^^^^^^^^^^^^^^^^^^^^^^^^^^^^^^^^^^
  File "/home/zaffarelli/.virtualenvs/owod/lib/python3.11/site-packages/django/contrib/admin/options.py", line 2065, in changelist_view
    "selection_note": _("0 of %(cnt)s selected") % {"cnt": len(cl.result_list)},
                                                           ^^^^^^^^^^^^^^^^^^^
  File "/home/zaffarelli/.virtualenvs/owod/lib/python3.11/site-packages/django/db/models/query.py", line 380, in __len__
    self._fetch_all()
  File "/home/zaffarelli/.virtualenvs/owod/lib/python3.11/site-packages/django/db/models/query.py", line 1881, in _fetch_all
    self._result_cache = list(self._iterable_class(self))
                         ^^^^^^^^^^^^^^^^^^^^^^^^^^^^^^^^
  File "/home/zaffarelli/.virtualenvs/owod/lib/python3.11/site-packages/django/db/models/query.py", line 91, in __iter__
    results = compiler.execute_sql(
              ^^^^^^^^^^^^^^^^^^^^^
  File "/home/zaffarelli/.virtualenvs/owod/lib/python3.11/site-packages/django/db/models/sql/compiler.py", line 1560, in execute_sql
    cursor.execute(sql, params)
  File "/home/zaffarelli/.virtualenvs/owod/lib/python3.11/site-packages/django/db/backends/utils.py", line 102, in execute
    return super().execute(sql, params)
           ^^^^^^^^^^^^^^^^^^^^^^^^^^^^
  File "/home/zaffarelli/.virtualenvs/owod/lib/python3.11/site-packages/django/db/backends/utils.py", line 67, in execute
    return self._execute_with_wrappers(
           ^^^^^^^^^^^^^^^^^^^^^^^^^^^^
  File "/home/zaffarelli/.virtualenvs/owod/lib/python3.11/site-packages/django/db/backends/utils.py", line 80, in _execute_with_wrappers
    return executor(sql, params, many, context)
           ^^^^^^^^^^^^^^^^^^^^^^^^^^^^^^^^^^^^
  File "/home/zaffarelli/.virtualenvs/owod/lib/python3.11/site-packages/django/db/backends/utils.py", line 84, in _execute
    with self.db.wrap_database_errors:
  File "/home/zaffarelli/.virtualenvs/owod/lib/python3.11/site-packages/django/db/utils.py", line 91, in __exit__
    raise dj_exc_value.with_traceback(traceback) from exc_value
  File "/home/zaffarelli/.virtualenvs/owod/lib/python3.11/site-packages/django/db/backends/utils.py", line 89, in _execute
    return self.cursor.execute(sql, params)
           ^^^^^^^^^^^^^^^^^^^^^^^^^^^^^^^^
  File "/home/zaffarelli/.virtualenvs/owod/lib/python3.11/site-packages/django/db/backends/mysql/base.py", line 75, in execute
    return self.cursor.execute(query, args)
           ^^^^^^^^^^^^^^^^^^^^^^^^^^^^^^^^
  File "/home/zaffarelli/.virtualenvs/owod/lib64/python3.11/site-packages/MySQLdb/cursors.py", line 206, in execute
    res = self._query(query)
          ^^^^^^^^^^^^^^^^^^
  File "/home/zaffarelli/.virtualenvs/owod/lib64/python3.11/site-packages/MySQLdb/cursors.py", line 319, in _query
    db.query(q)
  File "/home/zaffarelli/.virtualenvs/owod/lib64/python3.11/site-packages/MySQLdb/connections.py", line 254, in query
    _mysql.connection.query(self, query)
django.db.utils.OperationalError: (1054, "Unknown column 'storytelling_hotspot.city_id' in 'field list'")
[04/06 13:35:17] "GET /admin/storytelling/hotspot/ HTTP/1.1" 500 196352
[04/06 14:06:33] Internal Server Error: /ajax/display/map/hamburg/
Traceback (most recent call last):
  File "/home/zaffarelli/.virtualenvs/owod/lib/python3.11/site-packages/django/core/handlers/exception.py", line 55, in inner
    response = get_response(request)
               ^^^^^^^^^^^^^^^^^^^^^
  File "/home/zaffarelli/.virtualenvs/owod/lib/python3.11/site-packages/django/core/handlers/base.py", line 197, in _get_response
    response = wrapped_callback(request, *callback_args, **callback_kwargs)
               ^^^^^^^^^^^^^^^^^^^^^^^^^^^^^^^^^^^^^^^^^^^^^^^^^^^^^^^^^^^^
  File "/home/zaffarelli/Perso/github/wawwod/storytelling/views/base.py", line 136, in display_map
    context = get_districts(x)
              ^^^^^^^^^^^^^^^^
  File "/home/zaffarelli/Perso/github/wawwod/collector/utils/data_collection.py", line 557, in get_districts
    context['hotspots'][str(hs.id)] = {
    ~~~~~~~^^^^^^^^^^^^
KeyError: 'hotspots'
[04/06 14:06:33] "GET /ajax/display/map/hamburg/ HTTP/1.1" 500 89959
[04/06 14:06:39] Internal Server Error: /ajax/display/map/hamburg/
Traceback (most recent call last):
  File "/home/zaffarelli/.virtualenvs/owod/lib/python3.11/site-packages/django/core/handlers/exception.py", line 55, in inner
    response = get_response(request)
               ^^^^^^^^^^^^^^^^^^^^^
  File "/home/zaffarelli/.virtualenvs/owod/lib/python3.11/site-packages/django/core/handlers/base.py", line 197, in _get_response
    response = wrapped_callback(request, *callback_args, **callback_kwargs)
               ^^^^^^^^^^^^^^^^^^^^^^^^^^^^^^^^^^^^^^^^^^^^^^^^^^^^^^^^^^^^
  File "/home/zaffarelli/Perso/github/wawwod/storytelling/views/base.py", line 136, in display_map
    context = get_districts(x)
              ^^^^^^^^^^^^^^^^
  File "/home/zaffarelli/Perso/github/wawwod/collector/utils/data_collection.py", line 557, in get_districts
    context['hotspots'][str(hs.id)] = {
    ~~~~~~~^^^^^^^^^^^^
KeyError: 'hotspots'
[04/06 14:06:39] "GET /ajax/display/map/hamburg/ HTTP/1.1" 500 89959
[04/06 14:07:49] Internal Server Error: /ajax/display/map/hamburg/
Traceback (most recent call last):
  File "/home/zaffarelli/.virtualenvs/owod/lib/python3.11/site-packages/django/core/handlers/exception.py", line 55, in inner
    response = get_response(request)
               ^^^^^^^^^^^^^^^^^^^^^
  File "/home/zaffarelli/.virtualenvs/owod/lib/python3.11/site-packages/django/core/handlers/base.py", line 197, in _get_response
    response = wrapped_callback(request, *callback_args, **callback_kwargs)
               ^^^^^^^^^^^^^^^^^^^^^^^^^^^^^^^^^^^^^^^^^^^^^^^^^^^^^^^^^^^^
  File "/home/zaffarelli/Perso/github/wawwod/storytelling/views/base.py", line 136, in display_map
    context = get_districts(x)
              ^^^^^^^^^^^^^^^^
  File "/home/zaffarelli/Perso/github/wawwod/collector/utils/data_collection.py", line 557, in get_districts
    context['hotspots'].append({
    ~~~~~~~^^^^^^^^^^^^
KeyError: 'hotspots'
[04/06 14:07:49] "GET /ajax/display/map/hamburg/ HTTP/1.1" 500 89946
[04/06 14:24:17] Internal Server Error: /ajax/display/map/hamburg/
Traceback (most recent call last):
  File "/home/zaffarelli/.virtualenvs/owod/lib/python3.11/site-packages/django/core/handlers/exception.py", line 55, in inner
    response = get_response(request)
               ^^^^^^^^^^^^^^^^^^^^^
  File "/home/zaffarelli/.virtualenvs/owod/lib/python3.11/site-packages/django/core/handlers/base.py", line 197, in _get_response
    response = wrapped_callback(request, *callback_args, **callback_kwargs)
               ^^^^^^^^^^^^^^^^^^^^^^^^^^^^^^^^^^^^^^^^^^^^^^^^^^^^^^^^^^^^
  File "/home/zaffarelli/Perso/github/wawwod/storytelling/views/base.py", line 136, in display_map
    context = get_districts(x)
              ^^^^^^^^^^^^^^^^
  File "/home/zaffarelli/Perso/github/wawwod/collector/utils/data_collection.py", line 557, in get_districts
    context['hotspots'][str(hs.id)] = {
    ~~~~~~~~~~~~~~~~~~~^^^^^^^^^^^^
TypeError: list indices must be integers or slices, not str
[04/06 14:24:17] "GET /ajax/display/map/hamburg/ HTTP/1.1" 500 90113
[04/06 17:40:02] "GET /static/collector/wawwod_rab.svg HTTP/1.1" 404 1828
[04/06 17:40:12] "GET /static/collector/wawwod_rab.svg HTTP/1.1" 404 1828
[04/06 19:22:01] Internal Server Error: /ajax/display/map/hamburg/
Traceback (most recent call last):
  File "/home/zaffarelli/.virtualenvs/owod/lib/python3.11/site-packages/django/core/handlers/exception.py", line 55, in inner
    response = get_response(request)
               ^^^^^^^^^^^^^^^^^^^^^
  File "/home/zaffarelli/.virtualenvs/owod/lib/python3.11/site-packages/django/core/handlers/base.py", line 197, in _get_response
    response = wrapped_callback(request, *callback_args, **callback_kwargs)
               ^^^^^^^^^^^^^^^^^^^^^^^^^^^^^^^^^^^^^^^^^^^^^^^^^^^^^^^^^^^^
  File "/home/zaffarelli/Perso/github/wawwod/storytelling/views/base.py", line 136, in display_map
    context = get_districts(x)
              ^^^^^^^^^^^^^^^^
  File "/home/zaffarelli/Perso/github/wawwod/collector/utils/data_collection.py", line 557, in get_districts
    context['hotspots'].append({
    ^^^^^^^^^^^^^^^^^^^^^^^^^^
AttributeError: 'dict' object has no attribute 'append'
[04/06 19:22:01] "GET /ajax/display/map/hamburg/ HTTP/1.1" 500 90187
[05/06 01:06:57] Not Found: /favicon.ico
[05/06 01:06:57] "GET /favicon.ico HTTP/1.1" 404 8687
[05/06 01:25:21] Not Found: /favicon.ico
[05/06 01:25:21] "GET /favicon.ico HTTP/1.1" 404 8687
[05/06 02:06:28] Not Found: /favicon.ico
[05/06 03:14:29] Not Found: /favicon.ico
[05/06 13:53:59] Not Found: /favicon.ico
[05/06 13:57:09] "GET /static/storytelling/fonts/Lato-Regular.ttf HTTP/1.1" 404 1861
[05/06 13:57:41] "GET /static/storytelling/fonts/Lato-Regular.ttf HTTP/1.1" 404 1861
[05/06 14:01:48] "GET /static/storytelling/fonts/Lato-Regular.ttf HTTP/1.1" 404 1861
[05/06 14:12:15] Internal Server Error: /ajax/editable/updown/
Traceback (most recent call last):
  File "/home/zaffarelli/.virtualenvs/owod/lib/python3.11/site-packages/django/db/backends/utils.py", line 89, in _execute
    return self.cursor.execute(sql, params)
           ^^^^^^^^^^^^^^^^^^^^^^^^^^^^^^^^
  File "/home/zaffarelli/.virtualenvs/owod/lib/python3.11/site-packages/django/db/backends/mysql/base.py", line 75, in execute
    return self.cursor.execute(query, args)
           ^^^^^^^^^^^^^^^^^^^^^^^^^^^^^^^^
  File "/home/zaffarelli/.virtualenvs/owod/lib64/python3.11/site-packages/MySQLdb/cursors.py", line 206, in execute
    res = self._query(query)
          ^^^^^^^^^^^^^^^^^^
  File "/home/zaffarelli/.virtualenvs/owod/lib64/python3.11/site-packages/MySQLdb/cursors.py", line 319, in _query
    db.query(q)
  File "/home/zaffarelli/.virtualenvs/owod/lib64/python3.11/site-packages/MySQLdb/connections.py", line 254, in query
    _mysql.connection.query(self, query)
MySQLdb.DataError: (1264, "Out of range value for column 'background8' at row 1")

The above exception was the direct cause of the following exception:

Traceback (most recent call last):
  File "/home/zaffarelli/.virtualenvs/owod/lib/python3.11/site-packages/django/core/handlers/exception.py", line 55, in inner
    response = get_response(request)
               ^^^^^^^^^^^^^^^^^^^^^
  File "/home/zaffarelli/.virtualenvs/owod/lib/python3.11/site-packages/django/core/handlers/base.py", line 197, in _get_response
    response = wrapped_callback(request, *callback_args, **callback_kwargs)
               ^^^^^^^^^^^^^^^^^^^^^^^^^^^^^^^^^^^^^^^^^^^^^^^^^^^^^^^^^^^^
  File "/home/zaffarelli/.virtualenvs/owod/lib/python3.11/site-packages/django/views/decorators/csrf.py", line 56, in wrapper_view
    return view_func(*args, **kwargs)
           ^^^^^^^^^^^^^^^^^^^^^^^^^^
  File "/home/zaffarelli/Perso/github/wawwod/collector/views/base.py", line 129, in updown
    item.save()
  File "/home/zaffarelli/.virtualenvs/owod/lib/python3.11/site-packages/django/db/models/base.py", line 814, in save
    self.save_base(
  File "/home/zaffarelli/.virtualenvs/owod/lib/python3.11/site-packages/django/db/models/base.py", line 877, in save_base
    updated = self._save_table(
              ^^^^^^^^^^^^^^^^^
  File "/home/zaffarelli/.virtualenvs/owod/lib/python3.11/site-packages/django/db/models/base.py", line 990, in _save_table
    updated = self._do_update(
              ^^^^^^^^^^^^^^^^
  File "/home/zaffarelli/.virtualenvs/owod/lib/python3.11/site-packages/django/db/models/base.py", line 1054, in _do_update
    return filtered._update(values) > 0
           ^^^^^^^^^^^^^^^^^^^^^^^^
  File "/home/zaffarelli/.virtualenvs/owod/lib/python3.11/site-packages/django/db/models/query.py", line 1231, in _update
    return query.get_compiler(self.db).execute_sql(CURSOR)
           ^^^^^^^^^^^^^^^^^^^^^^^^^^^^^^^^^^^^^^^^^^^^^^^
  File "/home/zaffarelli/.virtualenvs/owod/lib/python3.11/site-packages/django/db/models/sql/compiler.py", line 1982, in execute_sql
    cursor = super().execute_sql(result_type)
             ^^^^^^^^^^^^^^^^^^^^^^^^^^^^^^^^
  File "/home/zaffarelli/.virtualenvs/owod/lib/python3.11/site-packages/django/db/models/sql/compiler.py", line 1560, in execute_sql
    cursor.execute(sql, params)
  File "/home/zaffarelli/.virtualenvs/owod/lib/python3.11/site-packages/django/db/backends/utils.py", line 102, in execute
    return super().execute(sql, params)
           ^^^^^^^^^^^^^^^^^^^^^^^^^^^^
  File "/home/zaffarelli/.virtualenvs/owod/lib/python3.11/site-packages/django/db/backends/utils.py", line 67, in execute
    return self._execute_with_wrappers(
           ^^^^^^^^^^^^^^^^^^^^^^^^^^^^
  File "/home/zaffarelli/.virtualenvs/owod/lib/python3.11/site-packages/django/db/backends/utils.py", line 80, in _execute_with_wrappers
    return executor(sql, params, many, context)
           ^^^^^^^^^^^^^^^^^^^^^^^^^^^^^^^^^^^^
  File "/home/zaffarelli/.virtualenvs/owod/lib/python3.11/site-packages/django/db/backends/utils.py", line 84, in _execute
    with self.db.wrap_database_errors:
  File "/home/zaffarelli/.virtualenvs/owod/lib/python3.11/site-packages/django/db/utils.py", line 91, in __exit__
    raise dj_exc_value.with_traceback(traceback) from exc_value
  File "/home/zaffarelli/.virtualenvs/owod/lib/python3.11/site-packages/django/db/backends/utils.py", line 89, in _execute
    return self.cursor.execute(sql, params)
           ^^^^^^^^^^^^^^^^^^^^^^^^^^^^^^^^
  File "/home/zaffarelli/.virtualenvs/owod/lib/python3.11/site-packages/django/db/backends/mysql/base.py", line 75, in execute
    return self.cursor.execute(query, args)
           ^^^^^^^^^^^^^^^^^^^^^^^^^^^^^^^^
  File "/home/zaffarelli/.virtualenvs/owod/lib64/python3.11/site-packages/MySQLdb/cursors.py", line 206, in execute
    res = self._query(query)
          ^^^^^^^^^^^^^^^^^^
  File "/home/zaffarelli/.virtualenvs/owod/lib64/python3.11/site-packages/MySQLdb/cursors.py", line 319, in _query
    db.query(q)
  File "/home/zaffarelli/.virtualenvs/owod/lib64/python3.11/site-packages/MySQLdb/connections.py", line 254, in query
    _mysql.connection.query(self, query)
django.db.utils.DataError: (1264, "Out of range value for column 'background8' at row 1")
[05/06 14:12:15] "POST /ajax/editable/updown/ HTTP/1.1" 500 25907
[05/06 14:32:53] "GET /static/collector/clans/blood_brothers.webp HTTP/1.1" 404 1861
[05/06 14:32:53] "GET /static/collector/clans/gargoyle.webp HTTP/1.1" 404 1843
[05/06 14:32:57] "GET /static/collector/clans/gargoyle.webp HTTP/1.1" 404 1843
[05/06 14:32:57] "GET /static/collector/clans/blood_brothers.webp HTTP/1.1" 404 1861
[07/06 01:59:56] "GET /static/storytelling/fonts/Lato-Regular.ttf HTTP/1.1" 404 1861
[07/06 02:48:58] "GET /static/storytelling/fonts/Lato-Regular.ttf HTTP/1.1" 404 1861
[07/06 02:53:16] "GET /static/storytelling/fonts/Lato-Regular.ttf HTTP/1.1" 404 1861
[07/06 02:54:08] "GET /static/storytelling/fonts/Lato-Regular.ttf HTTP/1.1" 404 1861
[07/06 02:59:06] Internal Server Error: /ajax/editable/updown/
Traceback (most recent call last):
  File "/home/zaffarelli/.virtualenvs/owod/lib/python3.11/site-packages/django/core/handlers/exception.py", line 55, in inner
    response = get_response(request)
               ^^^^^^^^^^^^^^^^^^^^^
  File "/home/zaffarelli/.virtualenvs/owod/lib/python3.11/site-packages/django/core/handlers/base.py", line 197, in _get_response
    response = wrapped_callback(request, *callback_args, **callback_kwargs)
               ^^^^^^^^^^^^^^^^^^^^^^^^^^^^^^^^^^^^^^^^^^^^^^^^^^^^^^^^^^^^
  File "/home/zaffarelli/.virtualenvs/owod/lib/python3.11/site-packages/django/views/decorators/csrf.py", line 56, in wrapper_view
    return view_func(*args, **kwargs)
           ^^^^^^^^^^^^^^^^^^^^^^^^^^
  File "/home/zaffarelli/Perso/github/wawwod/collector/views/base.py", line 123, in updown
    item = Creature.objects.get(rid=rid)
           ^^^^^^^^^^^^^^^^^^^^^^^^^^^^^
  File "/home/zaffarelli/.virtualenvs/owod/lib/python3.11/site-packages/django/db/models/manager.py", line 87, in manager_method
    return getattr(self.get_queryset(), name)(*args, **kwargs)
           ^^^^^^^^^^^^^^^^^^^^^^^^^^^^^^^^^^^^^^^^^^^^^^^^^^^
  File "/home/zaffarelli/.virtualenvs/owod/lib/python3.11/site-packages/django/db/models/query.py", line 637, in get
    raise self.model.DoesNotExist(
collector.models.creatures.Creature.DoesNotExist: Creature matching query does not exist.
[07/06 02:59:06] "POST /ajax/editable/updown/ HTTP/1.1" 500 21902
[07/06 02:59:07] Internal Server Error: /ajax/editable/updown/
Traceback (most recent call last):
  File "/home/zaffarelli/.virtualenvs/owod/lib/python3.11/site-packages/django/core/handlers/exception.py", line 55, in inner
    response = get_response(request)
               ^^^^^^^^^^^^^^^^^^^^^
  File "/home/zaffarelli/.virtualenvs/owod/lib/python3.11/site-packages/django/core/handlers/base.py", line 197, in _get_response
    response = wrapped_callback(request, *callback_args, **callback_kwargs)
               ^^^^^^^^^^^^^^^^^^^^^^^^^^^^^^^^^^^^^^^^^^^^^^^^^^^^^^^^^^^^
  File "/home/zaffarelli/.virtualenvs/owod/lib/python3.11/site-packages/django/views/decorators/csrf.py", line 56, in wrapper_view
    return view_func(*args, **kwargs)
           ^^^^^^^^^^^^^^^^^^^^^^^^^^
  File "/home/zaffarelli/Perso/github/wawwod/collector/views/base.py", line 123, in updown
    item = Creature.objects.get(rid=rid)
           ^^^^^^^^^^^^^^^^^^^^^^^^^^^^^
  File "/home/zaffarelli/.virtualenvs/owod/lib/python3.11/site-packages/django/db/models/manager.py", line 87, in manager_method
    return getattr(self.get_queryset(), name)(*args, **kwargs)
           ^^^^^^^^^^^^^^^^^^^^^^^^^^^^^^^^^^^^^^^^^^^^^^^^^^^
  File "/home/zaffarelli/.virtualenvs/owod/lib/python3.11/site-packages/django/db/models/query.py", line 637, in get
    raise self.model.DoesNotExist(
collector.models.creatures.Creature.DoesNotExist: Creature matching query does not exist.
[07/06 02:59:07] "POST /ajax/editable/updown/ HTTP/1.1" 500 21902
[07/06 02:59:10] Internal Server Error: /ajax/editable/updown/
Traceback (most recent call last):
  File "/home/zaffarelli/.virtualenvs/owod/lib/python3.11/site-packages/django/core/handlers/exception.py", line 55, in inner
    response = get_response(request)
               ^^^^^^^^^^^^^^^^^^^^^
  File "/home/zaffarelli/.virtualenvs/owod/lib/python3.11/site-packages/django/core/handlers/base.py", line 197, in _get_response
    response = wrapped_callback(request, *callback_args, **callback_kwargs)
               ^^^^^^^^^^^^^^^^^^^^^^^^^^^^^^^^^^^^^^^^^^^^^^^^^^^^^^^^^^^^
  File "/home/zaffarelli/.virtualenvs/owod/lib/python3.11/site-packages/django/views/decorators/csrf.py", line 56, in wrapper_view
    return view_func(*args, **kwargs)
           ^^^^^^^^^^^^^^^^^^^^^^^^^^
  File "/home/zaffarelli/Perso/github/wawwod/collector/views/base.py", line 123, in updown
    item = Creature.objects.get(rid=rid)
           ^^^^^^^^^^^^^^^^^^^^^^^^^^^^^
  File "/home/zaffarelli/.virtualenvs/owod/lib/python3.11/site-packages/django/db/models/manager.py", line 87, in manager_method
    return getattr(self.get_queryset(), name)(*args, **kwargs)
           ^^^^^^^^^^^^^^^^^^^^^^^^^^^^^^^^^^^^^^^^^^^^^^^^^^^
  File "/home/zaffarelli/.virtualenvs/owod/lib/python3.11/site-packages/django/db/models/query.py", line 637, in get
    raise self.model.DoesNotExist(
collector.models.creatures.Creature.DoesNotExist: Creature matching query does not exist.
[07/06 02:59:10] "POST /ajax/editable/updown/ HTTP/1.1" 500 21902
[07/06 02:59:10] Internal Server Error: /ajax/editable/updown/
Traceback (most recent call last):
  File "/home/zaffarelli/.virtualenvs/owod/lib/python3.11/site-packages/django/core/handlers/exception.py", line 55, in inner
    response = get_response(request)
               ^^^^^^^^^^^^^^^^^^^^^
  File "/home/zaffarelli/.virtualenvs/owod/lib/python3.11/site-packages/django/core/handlers/base.py", line 197, in _get_response
    response = wrapped_callback(request, *callback_args, **callback_kwargs)
               ^^^^^^^^^^^^^^^^^^^^^^^^^^^^^^^^^^^^^^^^^^^^^^^^^^^^^^^^^^^^
  File "/home/zaffarelli/.virtualenvs/owod/lib/python3.11/site-packages/django/views/decorators/csrf.py", line 56, in wrapper_view
    return view_func(*args, **kwargs)
           ^^^^^^^^^^^^^^^^^^^^^^^^^^
  File "/home/zaffarelli/Perso/github/wawwod/collector/views/base.py", line 123, in updown
    item = Creature.objects.get(rid=rid)
           ^^^^^^^^^^^^^^^^^^^^^^^^^^^^^
  File "/home/zaffarelli/.virtualenvs/owod/lib/python3.11/site-packages/django/db/models/manager.py", line 87, in manager_method
    return getattr(self.get_queryset(), name)(*args, **kwargs)
           ^^^^^^^^^^^^^^^^^^^^^^^^^^^^^^^^^^^^^^^^^^^^^^^^^^^
  File "/home/zaffarelli/.virtualenvs/owod/lib/python3.11/site-packages/django/db/models/query.py", line 637, in get
    raise self.model.DoesNotExist(
collector.models.creatures.Creature.DoesNotExist: Creature matching query does not exist.
[07/06 02:59:10] "POST /ajax/editable/updown/ HTTP/1.1" 500 21902
[07/06 02:59:11] Internal Server Error: /ajax/editable/updown/
Traceback (most recent call last):
  File "/home/zaffarelli/.virtualenvs/owod/lib/python3.11/site-packages/django/core/handlers/exception.py", line 55, in inner
    response = get_response(request)
               ^^^^^^^^^^^^^^^^^^^^^
  File "/home/zaffarelli/.virtualenvs/owod/lib/python3.11/site-packages/django/core/handlers/base.py", line 197, in _get_response
    response = wrapped_callback(request, *callback_args, **callback_kwargs)
               ^^^^^^^^^^^^^^^^^^^^^^^^^^^^^^^^^^^^^^^^^^^^^^^^^^^^^^^^^^^^
  File "/home/zaffarelli/.virtualenvs/owod/lib/python3.11/site-packages/django/views/decorators/csrf.py", line 56, in wrapper_view
    return view_func(*args, **kwargs)
           ^^^^^^^^^^^^^^^^^^^^^^^^^^
  File "/home/zaffarelli/Perso/github/wawwod/collector/views/base.py", line 123, in updown
    item = Creature.objects.get(rid=rid)
           ^^^^^^^^^^^^^^^^^^^^^^^^^^^^^
  File "/home/zaffarelli/.virtualenvs/owod/lib/python3.11/site-packages/django/db/models/manager.py", line 87, in manager_method
    return getattr(self.get_queryset(), name)(*args, **kwargs)
           ^^^^^^^^^^^^^^^^^^^^^^^^^^^^^^^^^^^^^^^^^^^^^^^^^^^
  File "/home/zaffarelli/.virtualenvs/owod/lib/python3.11/site-packages/django/db/models/query.py", line 637, in get
    raise self.model.DoesNotExist(
collector.models.creatures.Creature.DoesNotExist: Creature matching query does not exist.
[07/06 02:59:11] "POST /ajax/editable/updown/ HTTP/1.1" 500 21902
[07/06 02:59:12] Internal Server Error: /ajax/editable/updown/
Traceback (most recent call last):
  File "/home/zaffarelli/.virtualenvs/owod/lib/python3.11/site-packages/django/core/handlers/exception.py", line 55, in inner
    response = get_response(request)
               ^^^^^^^^^^^^^^^^^^^^^
  File "/home/zaffarelli/.virtualenvs/owod/lib/python3.11/site-packages/django/core/handlers/base.py", line 197, in _get_response
    response = wrapped_callback(request, *callback_args, **callback_kwargs)
               ^^^^^^^^^^^^^^^^^^^^^^^^^^^^^^^^^^^^^^^^^^^^^^^^^^^^^^^^^^^^
  File "/home/zaffarelli/.virtualenvs/owod/lib/python3.11/site-packages/django/views/decorators/csrf.py", line 56, in wrapper_view
    return view_func(*args, **kwargs)
           ^^^^^^^^^^^^^^^^^^^^^^^^^^
  File "/home/zaffarelli/Perso/github/wawwod/collector/views/base.py", line 123, in updown
    item = Creature.objects.get(rid=rid)
           ^^^^^^^^^^^^^^^^^^^^^^^^^^^^^
  File "/home/zaffarelli/.virtualenvs/owod/lib/python3.11/site-packages/django/db/models/manager.py", line 87, in manager_method
    return getattr(self.get_queryset(), name)(*args, **kwargs)
           ^^^^^^^^^^^^^^^^^^^^^^^^^^^^^^^^^^^^^^^^^^^^^^^^^^^
  File "/home/zaffarelli/.virtualenvs/owod/lib/python3.11/site-packages/django/db/models/query.py", line 637, in get
    raise self.model.DoesNotExist(
collector.models.creatures.Creature.DoesNotExist: Creature matching query does not exist.
[07/06 02:59:12] "POST /ajax/editable/updown/ HTTP/1.1" 500 21901
[07/06 02:59:13] Internal Server Error: /ajax/editable/updown/
Traceback (most recent call last):
  File "/home/zaffarelli/.virtualenvs/owod/lib/python3.11/site-packages/django/core/handlers/exception.py", line 55, in inner
    response = get_response(request)
               ^^^^^^^^^^^^^^^^^^^^^
  File "/home/zaffarelli/.virtualenvs/owod/lib/python3.11/site-packages/django/core/handlers/base.py", line 197, in _get_response
    response = wrapped_callback(request, *callback_args, **callback_kwargs)
               ^^^^^^^^^^^^^^^^^^^^^^^^^^^^^^^^^^^^^^^^^^^^^^^^^^^^^^^^^^^^
  File "/home/zaffarelli/.virtualenvs/owod/lib/python3.11/site-packages/django/views/decorators/csrf.py", line 56, in wrapper_view
    return view_func(*args, **kwargs)
           ^^^^^^^^^^^^^^^^^^^^^^^^^^
  File "/home/zaffarelli/Perso/github/wawwod/collector/views/base.py", line 123, in updown
    item = Creature.objects.get(rid=rid)
           ^^^^^^^^^^^^^^^^^^^^^^^^^^^^^
  File "/home/zaffarelli/.virtualenvs/owod/lib/python3.11/site-packages/django/db/models/manager.py", line 87, in manager_method
    return getattr(self.get_queryset(), name)(*args, **kwargs)
           ^^^^^^^^^^^^^^^^^^^^^^^^^^^^^^^^^^^^^^^^^^^^^^^^^^^
  File "/home/zaffarelli/.virtualenvs/owod/lib/python3.11/site-packages/django/db/models/query.py", line 637, in get
    raise self.model.DoesNotExist(
collector.models.creatures.Creature.DoesNotExist: Creature matching query does not exist.
[07/06 02:59:13] "POST /ajax/editable/updown/ HTTP/1.1" 500 21901
[07/06 02:59:40] Internal Server Error: /ajax/editable/updown/
Traceback (most recent call last):
  File "/home/zaffarelli/.virtualenvs/owod/lib/python3.11/site-packages/django/core/handlers/exception.py", line 55, in inner
    response = get_response(request)
               ^^^^^^^^^^^^^^^^^^^^^
  File "/home/zaffarelli/.virtualenvs/owod/lib/python3.11/site-packages/django/core/handlers/base.py", line 197, in _get_response
    response = wrapped_callback(request, *callback_args, **callback_kwargs)
               ^^^^^^^^^^^^^^^^^^^^^^^^^^^^^^^^^^^^^^^^^^^^^^^^^^^^^^^^^^^^
  File "/home/zaffarelli/.virtualenvs/owod/lib/python3.11/site-packages/django/views/decorators/csrf.py", line 56, in wrapper_view
    return view_func(*args, **kwargs)
           ^^^^^^^^^^^^^^^^^^^^^^^^^^
  File "/home/zaffarelli/Perso/github/wawwod/collector/views/base.py", line 123, in updown
    item = Creature.objects.get(rid=rid)
           ^^^^^^^^^^^^^^^^^^^^^^^^^^^^^
  File "/home/zaffarelli/.virtualenvs/owod/lib/python3.11/site-packages/django/db/models/manager.py", line 87, in manager_method
    return getattr(self.get_queryset(), name)(*args, **kwargs)
           ^^^^^^^^^^^^^^^^^^^^^^^^^^^^^^^^^^^^^^^^^^^^^^^^^^^
  File "/home/zaffarelli/.virtualenvs/owod/lib/python3.11/site-packages/django/db/models/query.py", line 637, in get
    raise self.model.DoesNotExist(
collector.models.creatures.Creature.DoesNotExist: Creature matching query does not exist.
[07/06 02:59:40] "POST /ajax/editable/updown/ HTTP/1.1" 500 21902
[07/06 02:59:42] Internal Server Error: /ajax/editable/updown/
Traceback (most recent call last):
  File "/home/zaffarelli/.virtualenvs/owod/lib/python3.11/site-packages/django/core/handlers/exception.py", line 55, in inner
    response = get_response(request)
               ^^^^^^^^^^^^^^^^^^^^^
  File "/home/zaffarelli/.virtualenvs/owod/lib/python3.11/site-packages/django/core/handlers/base.py", line 197, in _get_response
    response = wrapped_callback(request, *callback_args, **callback_kwargs)
               ^^^^^^^^^^^^^^^^^^^^^^^^^^^^^^^^^^^^^^^^^^^^^^^^^^^^^^^^^^^^
  File "/home/zaffarelli/.virtualenvs/owod/lib/python3.11/site-packages/django/views/decorators/csrf.py", line 56, in wrapper_view
    return view_func(*args, **kwargs)
           ^^^^^^^^^^^^^^^^^^^^^^^^^^
  File "/home/zaffarelli/Perso/github/wawwod/collector/views/base.py", line 123, in updown
    item = Creature.objects.get(rid=rid)
           ^^^^^^^^^^^^^^^^^^^^^^^^^^^^^
  File "/home/zaffarelli/.virtualenvs/owod/lib/python3.11/site-packages/django/db/models/manager.py", line 87, in manager_method
    return getattr(self.get_queryset(), name)(*args, **kwargs)
           ^^^^^^^^^^^^^^^^^^^^^^^^^^^^^^^^^^^^^^^^^^^^^^^^^^^
  File "/home/zaffarelli/.virtualenvs/owod/lib/python3.11/site-packages/django/db/models/query.py", line 637, in get
    raise self.model.DoesNotExist(
collector.models.creatures.Creature.DoesNotExist: Creature matching query does not exist.
[07/06 02:59:42] "POST /ajax/editable/updown/ HTTP/1.1" 500 21901
[07/06 02:59:44] Internal Server Error: /ajax/editable/updown/
Traceback (most recent call last):
  File "/home/zaffarelli/.virtualenvs/owod/lib/python3.11/site-packages/django/core/handlers/exception.py", line 55, in inner
    response = get_response(request)
               ^^^^^^^^^^^^^^^^^^^^^
  File "/home/zaffarelli/.virtualenvs/owod/lib/python3.11/site-packages/django/core/handlers/base.py", line 197, in _get_response
    response = wrapped_callback(request, *callback_args, **callback_kwargs)
               ^^^^^^^^^^^^^^^^^^^^^^^^^^^^^^^^^^^^^^^^^^^^^^^^^^^^^^^^^^^^
  File "/home/zaffarelli/.virtualenvs/owod/lib/python3.11/site-packages/django/views/decorators/csrf.py", line 56, in wrapper_view
    return view_func(*args, **kwargs)
           ^^^^^^^^^^^^^^^^^^^^^^^^^^
  File "/home/zaffarelli/Perso/github/wawwod/collector/views/base.py", line 123, in updown
    item = Creature.objects.get(rid=rid)
           ^^^^^^^^^^^^^^^^^^^^^^^^^^^^^
  File "/home/zaffarelli/.virtualenvs/owod/lib/python3.11/site-packages/django/db/models/manager.py", line 87, in manager_method
    return getattr(self.get_queryset(), name)(*args, **kwargs)
           ^^^^^^^^^^^^^^^^^^^^^^^^^^^^^^^^^^^^^^^^^^^^^^^^^^^
  File "/home/zaffarelli/.virtualenvs/owod/lib/python3.11/site-packages/django/db/models/query.py", line 637, in get
    raise self.model.DoesNotExist(
collector.models.creatures.Creature.DoesNotExist: Creature matching query does not exist.
[07/06 02:59:44] "POST /ajax/editable/updown/ HTTP/1.1" 500 21901
[07/06 03:01:06] Internal Server Error: /ajax/editable/updown/
Traceback (most recent call last):
  File "/home/zaffarelli/.virtualenvs/owod/lib/python3.11/site-packages/django/core/handlers/exception.py", line 55, in inner
    response = get_response(request)
               ^^^^^^^^^^^^^^^^^^^^^
  File "/home/zaffarelli/.virtualenvs/owod/lib/python3.11/site-packages/django/core/handlers/base.py", line 197, in _get_response
    response = wrapped_callback(request, *callback_args, **callback_kwargs)
               ^^^^^^^^^^^^^^^^^^^^^^^^^^^^^^^^^^^^^^^^^^^^^^^^^^^^^^^^^^^^
  File "/home/zaffarelli/.virtualenvs/owod/lib/python3.11/site-packages/django/views/decorators/csrf.py", line 56, in wrapper_view
    return view_func(*args, **kwargs)
           ^^^^^^^^^^^^^^^^^^^^^^^^^^
  File "/home/zaffarelli/Perso/github/wawwod/collector/views/base.py", line 123, in updown
    item = Creature.objects.get(rid=rid)
           ^^^^^^^^^^^^^^^^^^^^^^^^^^^^^
  File "/home/zaffarelli/.virtualenvs/owod/lib/python3.11/site-packages/django/db/models/manager.py", line 87, in manager_method
    return getattr(self.get_queryset(), name)(*args, **kwargs)
           ^^^^^^^^^^^^^^^^^^^^^^^^^^^^^^^^^^^^^^^^^^^^^^^^^^^
  File "/home/zaffarelli/.virtualenvs/owod/lib/python3.11/site-packages/django/db/models/query.py", line 637, in get
    raise self.model.DoesNotExist(
collector.models.creatures.Creature.DoesNotExist: Creature matching query does not exist.
[07/06 03:01:06] "POST /ajax/editable/updown/ HTTP/1.1" 500 21902
[07/06 03:04:11] "GET /static/storytelling/fonts/Lato-Regular.ttf HTTP/1.1" 404 1861
[07/06 03:04:41] "GET /static/storytelling/fonts/Lato-Regular.ttf HTTP/1.1" 404 1861
[07/06 04:09:27] Not Found: /favicon.ico
[07/06 04:09:27] "GET /favicon.ico HTTP/1.1" 404 8687
