[04:033656] Watching for file changes with StatReloader
[04:033703] Watching for file changes with StatReloader
[04:033711] "POST /ajax/character/svg2pdf/_martin_merkel/ HTTP/1.1" 200 16
[04:033716] "POST /ajax/character/save2svg/_martin_merkel/ HTTP/1.1" 200 16
[04:033729] "POST /ajax/character/svg2pdf/_martin_merkel/ HTTP/1.1" 200 16
[04:033827] "POST /ajax/character/svg2pdf/_martin_merkel/ HTTP/1.1" 200 16
[04:033833] "POST /ajax/character/svg2pdf/_martin_merkel/ HTTP/1.1" 200 16
[04:033837] "POST /ajax/character/svg2pdf/_martin_merkel/ HTTP/1.1" 200 16
[04:033933] /home/zaffarelli/Perso/github/wawwod/wawwod/settings.py changed, reloading.
[04/06 03:39:34] Watching for file changes with StatReloader
[04/06 03:44:14] /home/zaffarelli/Perso/github/wawwod/wawwod/settings.py changed, reloading.
[04/06 03:56:03] "GET /static/storytelling/fonts/Lato-Regular.ttf HTTP/1.1" 404 1861
[04/06 04:00:13] "GET /static/storytelling/fonts/Lato-Regular.ttf HTTP/1.1" 404 1861
[04/06 04:07:13] "GET /static/storytelling/fonts/Lato-Regular.ttf HTTP/1.1" 404 1861
[04/06 04:21:01] "GET /static/storytelling/fonts/Lato-Regular.ttf HTTP/1.1" 404 1861
[04/06 05:29:41] "GET /static/storytelling/fonts/Lato-Regular.ttf HTTP/1.1" 404 1861
[04/06 12:45:44] "GET /static/storytelling/fonts/Lato-Regular.ttf HTTP/1.1" 404 1861
[04/06 13:35:17] Internal Server Error: /admin/storytelling/hotspot/
Traceback (most recent call last):
  File "/home/zaffarelli/.virtualenvs/owod/lib/python3.11/site-packages/django/db/backends/utils.py", line 89, in _execute
    return self.cursor.execute(sql, params)
           ^^^^^^^^^^^^^^^^^^^^^^^^^^^^^^^^
  File "/home/zaffarelli/.virtualenvs/owod/lib/python3.11/site-packages/django/db/backends/mysql/base.py", line 75, in execute
    return self.cursor.execute(query, args)
           ^^^^^^^^^^^^^^^^^^^^^^^^^^^^^^^^
  File "/home/zaffarelli/.virtualenvs/owod/lib64/python3.11/site-packages/MySQLdb/cursors.py", line 206, in execute
    res = self._query(query)
          ^^^^^^^^^^^^^^^^^^
  File "/home/zaffarelli/.virtualenvs/owod/lib64/python3.11/site-packages/MySQLdb/cursors.py", line 319, in _query
    db.query(q)
  File "/home/zaffarelli/.virtualenvs/owod/lib64/python3.11/site-packages/MySQLdb/connections.py", line 254, in query
    _mysql.connection.query(self, query)
MySQLdb.OperationalError: (1054, "Unknown column 'storytelling_hotspot.city_id' in 'field list'")

The above exception was the direct cause of the following exception:

Traceback (most recent call last):
  File "/home/zaffarelli/.virtualenvs/owod/lib/python3.11/site-packages/django/core/handlers/exception.py", line 55, in inner
    response = get_response(request)
               ^^^^^^^^^^^^^^^^^^^^^
  File "/home/zaffarelli/.virtualenvs/owod/lib/python3.11/site-packages/django/core/handlers/base.py", line 197, in _get_response
    response = wrapped_callback(request, *callback_args, **callback_kwargs)
               ^^^^^^^^^^^^^^^^^^^^^^^^^^^^^^^^^^^^^^^^^^^^^^^^^^^^^^^^^^^^
  File "/home/zaffarelli/.virtualenvs/owod/lib/python3.11/site-packages/django/contrib/admin/options.py", line 688, in wrapper
    return self.admin_site.admin_view(view)(*args, **kwargs)
           ^^^^^^^^^^^^^^^^^^^^^^^^^^^^^^^^^^^^^^^^^^^^^^^^^
  File "/home/zaffarelli/.virtualenvs/owod/lib/python3.11/site-packages/django/utils/decorators.py", line 134, in _wrapper_view
    response = view_func(request, *args, **kwargs)
               ^^^^^^^^^^^^^^^^^^^^^^^^^^^^^^^^^^^
  File "/home/zaffarelli/.virtualenvs/owod/lib/python3.11/site-packages/django/views/decorators/cache.py", line 62, in _wrapper_view_func
    response = view_func(request, *args, **kwargs)
               ^^^^^^^^^^^^^^^^^^^^^^^^^^^^^^^^^^^
  File "/home/zaffarelli/.virtualenvs/owod/lib/python3.11/site-packages/django/contrib/admin/sites.py", line 242, in inner
    return view(request, *args, **kwargs)
           ^^^^^^^^^^^^^^^^^^^^^^^^^^^^^^
  File "/home/zaffarelli/.virtualenvs/owod/lib/python3.11/site-packages/django/utils/decorators.py", line 46, in _wrapper
    return bound_method(*args, **kwargs)
           ^^^^^^^^^^^^^^^^^^^^^^^^^^^^^
  File "/home/zaffarelli/.virtualenvs/owod/lib/python3.11/site-packages/django/utils/decorators.py", line 134, in _wrapper_view
    response = view_func(request, *args, **kwargs)
               ^^^^^^^^^^^^^^^^^^^^^^^^^^^^^^^^^^^
  File "/home/zaffarelli/.virtualenvs/owod/lib/python3.11/site-packages/django/contrib/admin/options.py", line 2065, in changelist_view
    "selection_note": _("0 of %(cnt)s selected") % {"cnt": len(cl.result_list)},
                                                           ^^^^^^^^^^^^^^^^^^^
  File "/home/zaffarelli/.virtualenvs/owod/lib/python3.11/site-packages/django/db/models/query.py", line 380, in __len__
    self._fetch_all()
  File "/home/zaffarelli/.virtualenvs/owod/lib/python3.11/site-packages/django/db/models/query.py", line 1881, in _fetch_all
    self._result_cache = list(self._iterable_class(self))
                         ^^^^^^^^^^^^^^^^^^^^^^^^^^^^^^^^
  File "/home/zaffarelli/.virtualenvs/owod/lib/python3.11/site-packages/django/db/models/query.py", line 91, in __iter__
    results = compiler.execute_sql(
              ^^^^^^^^^^^^^^^^^^^^^
  File "/home/zaffarelli/.virtualenvs/owod/lib/python3.11/site-packages/django/db/models/sql/compiler.py", line 1560, in execute_sql
    cursor.execute(sql, params)
  File "/home/zaffarelli/.virtualenvs/owod/lib/python3.11/site-packages/django/db/backends/utils.py", line 102, in execute
    return super().execute(sql, params)
           ^^^^^^^^^^^^^^^^^^^^^^^^^^^^
  File "/home/zaffarelli/.virtualenvs/owod/lib/python3.11/site-packages/django/db/backends/utils.py", line 67, in execute
    return self._execute_with_wrappers(
           ^^^^^^^^^^^^^^^^^^^^^^^^^^^^
  File "/home/zaffarelli/.virtualenvs/owod/lib/python3.11/site-packages/django/db/backends/utils.py", line 80, in _execute_with_wrappers
    return executor(sql, params, many, context)
           ^^^^^^^^^^^^^^^^^^^^^^^^^^^^^^^^^^^^
  File "/home/zaffarelli/.virtualenvs/owod/lib/python3.11/site-packages/django/db/backends/utils.py", line 84, in _execute
    with self.db.wrap_database_errors:
  File "/home/zaffarelli/.virtualenvs/owod/lib/python3.11/site-packages/django/db/utils.py", line 91, in __exit__
    raise dj_exc_value.with_traceback(traceback) from exc_value
  File "/home/zaffarelli/.virtualenvs/owod/lib/python3.11/site-packages/django/db/backends/utils.py", line 89, in _execute
    return self.cursor.execute(sql, params)
           ^^^^^^^^^^^^^^^^^^^^^^^^^^^^^^^^
  File "/home/zaffarelli/.virtualenvs/owod/lib/python3.11/site-packages/django/db/backends/mysql/base.py", line 75, in execute
    return self.cursor.execute(query, args)
           ^^^^^^^^^^^^^^^^^^^^^^^^^^^^^^^^
  File "/home/zaffarelli/.virtualenvs/owod/lib64/python3.11/site-packages/MySQLdb/cursors.py", line 206, in execute
    res = self._query(query)
          ^^^^^^^^^^^^^^^^^^
  File "/home/zaffarelli/.virtualenvs/owod/lib64/python3.11/site-packages/MySQLdb/cursors.py", line 319, in _query
    db.query(q)
  File "/home/zaffarelli/.virtualenvs/owod/lib64/python3.11/site-packages/MySQLdb/connections.py", line 254, in query
    _mysql.connection.query(self, query)
django.db.utils.OperationalError: (1054, "Unknown column 'storytelling_hotspot.city_id' in 'field list'")
[04/06 13:35:17] "GET /admin/storytelling/hotspot/ HTTP/1.1" 500 196352
[04/06 14:06:33] Internal Server Error: /ajax/display/map/hamburg/
Traceback (most recent call last):
  File "/home/zaffarelli/.virtualenvs/owod/lib/python3.11/site-packages/django/core/handlers/exception.py", line 55, in inner
    response = get_response(request)
               ^^^^^^^^^^^^^^^^^^^^^
  File "/home/zaffarelli/.virtualenvs/owod/lib/python3.11/site-packages/django/core/handlers/base.py", line 197, in _get_response
    response = wrapped_callback(request, *callback_args, **callback_kwargs)
               ^^^^^^^^^^^^^^^^^^^^^^^^^^^^^^^^^^^^^^^^^^^^^^^^^^^^^^^^^^^^
  File "/home/zaffarelli/Perso/github/wawwod/storytelling/views/base.py", line 136, in display_map
    context = get_districts(x)
              ^^^^^^^^^^^^^^^^
  File "/home/zaffarelli/Perso/github/wawwod/collector/utils/data_collection.py", line 557, in get_districts
    context['hotspots'][str(hs.id)] = {
    ~~~~~~~^^^^^^^^^^^^
KeyError: 'hotspots'
[04/06 14:06:33] "GET /ajax/display/map/hamburg/ HTTP/1.1" 500 89959
[04/06 14:06:39] Internal Server Error: /ajax/display/map/hamburg/
Traceback (most recent call last):
  File "/home/zaffarelli/.virtualenvs/owod/lib/python3.11/site-packages/django/core/handlers/exception.py", line 55, in inner
    response = get_response(request)
               ^^^^^^^^^^^^^^^^^^^^^
  File "/home/zaffarelli/.virtualenvs/owod/lib/python3.11/site-packages/django/core/handlers/base.py", line 197, in _get_response
    response = wrapped_callback(request, *callback_args, **callback_kwargs)
               ^^^^^^^^^^^^^^^^^^^^^^^^^^^^^^^^^^^^^^^^^^^^^^^^^^^^^^^^^^^^
  File "/home/zaffarelli/Perso/github/wawwod/storytelling/views/base.py", line 136, in display_map
    context = get_districts(x)
              ^^^^^^^^^^^^^^^^
  File "/home/zaffarelli/Perso/github/wawwod/collector/utils/data_collection.py", line 557, in get_districts
    context['hotspots'][str(hs.id)] = {
    ~~~~~~~^^^^^^^^^^^^
KeyError: 'hotspots'
[04/06 14:06:39] "GET /ajax/display/map/hamburg/ HTTP/1.1" 500 89959
[04/06 14:07:49] Internal Server Error: /ajax/display/map/hamburg/
Traceback (most recent call last):
  File "/home/zaffarelli/.virtualenvs/owod/lib/python3.11/site-packages/django/core/handlers/exception.py", line 55, in inner
    response = get_response(request)
               ^^^^^^^^^^^^^^^^^^^^^
  File "/home/zaffarelli/.virtualenvs/owod/lib/python3.11/site-packages/django/core/handlers/base.py", line 197, in _get_response
    response = wrapped_callback(request, *callback_args, **callback_kwargs)
               ^^^^^^^^^^^^^^^^^^^^^^^^^^^^^^^^^^^^^^^^^^^^^^^^^^^^^^^^^^^^
  File "/home/zaffarelli/Perso/github/wawwod/storytelling/views/base.py", line 136, in display_map
    context = get_districts(x)
              ^^^^^^^^^^^^^^^^
  File "/home/zaffarelli/Perso/github/wawwod/collector/utils/data_collection.py", line 557, in get_districts
    context['hotspots'].append({
    ~~~~~~~^^^^^^^^^^^^
KeyError: 'hotspots'
[04/06 14:07:49] "GET /ajax/display/map/hamburg/ HTTP/1.1" 500 89946
[04/06 14:24:17] Internal Server Error: /ajax/display/map/hamburg/
Traceback (most recent call last):
  File "/home/zaffarelli/.virtualenvs/owod/lib/python3.11/site-packages/django/core/handlers/exception.py", line 55, in inner
    response = get_response(request)
               ^^^^^^^^^^^^^^^^^^^^^
  File "/home/zaffarelli/.virtualenvs/owod/lib/python3.11/site-packages/django/core/handlers/base.py", line 197, in _get_response
    response = wrapped_callback(request, *callback_args, **callback_kwargs)
               ^^^^^^^^^^^^^^^^^^^^^^^^^^^^^^^^^^^^^^^^^^^^^^^^^^^^^^^^^^^^
  File "/home/zaffarelli/Perso/github/wawwod/storytelling/views/base.py", line 136, in display_map
    context = get_districts(x)
              ^^^^^^^^^^^^^^^^
  File "/home/zaffarelli/Perso/github/wawwod/collector/utils/data_collection.py", line 557, in get_districts
    context['hotspots'][str(hs.id)] = {
    ~~~~~~~~~~~~~~~~~~~^^^^^^^^^^^^
TypeError: list indices must be integers or slices, not str
[04/06 14:24:17] "GET /ajax/display/map/hamburg/ HTTP/1.1" 500 90113
[04/06 17:40:02] "GET /static/collector/wawwod_rab.svg HTTP/1.1" 404 1828
[04/06 17:40:12] "GET /static/collector/wawwod_rab.svg HTTP/1.1" 404 1828
[04/06 19:22:01] Internal Server Error: /ajax/display/map/hamburg/
Traceback (most recent call last):
  File "/home/zaffarelli/.virtualenvs/owod/lib/python3.11/site-packages/django/core/handlers/exception.py", line 55, in inner
    response = get_response(request)
               ^^^^^^^^^^^^^^^^^^^^^
  File "/home/zaffarelli/.virtualenvs/owod/lib/python3.11/site-packages/django/core/handlers/base.py", line 197, in _get_response
    response = wrapped_callback(request, *callback_args, **callback_kwargs)
               ^^^^^^^^^^^^^^^^^^^^^^^^^^^^^^^^^^^^^^^^^^^^^^^^^^^^^^^^^^^^
  File "/home/zaffarelli/Perso/github/wawwod/storytelling/views/base.py", line 136, in display_map
    context = get_districts(x)
              ^^^^^^^^^^^^^^^^
  File "/home/zaffarelli/Perso/github/wawwod/collector/utils/data_collection.py", line 557, in get_districts
    context['hotspots'].append({
    ^^^^^^^^^^^^^^^^^^^^^^^^^^
AttributeError: 'dict' object has no attribute 'append'
[04/06 19:22:01] "GET /ajax/display/map/hamburg/ HTTP/1.1" 500 90187
[05/06 01:06:57] Not Found: /favicon.ico
[05/06 01:06:57] "GET /favicon.ico HTTP/1.1" 404 8687
[05/06 01:25:21] Not Found: /favicon.ico
[05/06 01:25:21] "GET /favicon.ico HTTP/1.1" 404 8687
[05/06 02:06:28] Not Found: /favicon.ico
[05/06 03:14:29] Not Found: /favicon.ico
[05/06 13:53:59] Not Found: /favicon.ico
[05/06 13:57:09] "GET /static/storytelling/fonts/Lato-Regular.ttf HTTP/1.1" 404 1861
[05/06 13:57:41] "GET /static/storytelling/fonts/Lato-Regular.ttf HTTP/1.1" 404 1861
[05/06 14:01:48] "GET /static/storytelling/fonts/Lato-Regular.ttf HTTP/1.1" 404 1861
[05/06 14:12:15] Internal Server Error: /ajax/editable/updown/
Traceback (most recent call last):
  File "/home/zaffarelli/.virtualenvs/owod/lib/python3.11/site-packages/django/db/backends/utils.py", line 89, in _execute
    return self.cursor.execute(sql, params)
           ^^^^^^^^^^^^^^^^^^^^^^^^^^^^^^^^
  File "/home/zaffarelli/.virtualenvs/owod/lib/python3.11/site-packages/django/db/backends/mysql/base.py", line 75, in execute
    return self.cursor.execute(query, args)
           ^^^^^^^^^^^^^^^^^^^^^^^^^^^^^^^^
  File "/home/zaffarelli/.virtualenvs/owod/lib64/python3.11/site-packages/MySQLdb/cursors.py", line 206, in execute
    res = self._query(query)
          ^^^^^^^^^^^^^^^^^^
  File "/home/zaffarelli/.virtualenvs/owod/lib64/python3.11/site-packages/MySQLdb/cursors.py", line 319, in _query
    db.query(q)
  File "/home/zaffarelli/.virtualenvs/owod/lib64/python3.11/site-packages/MySQLdb/connections.py", line 254, in query
    _mysql.connection.query(self, query)
MySQLdb.DataError: (1264, "Out of range value for column 'background8' at row 1")

The above exception was the direct cause of the following exception:

Traceback (most recent call last):
  File "/home/zaffarelli/.virtualenvs/owod/lib/python3.11/site-packages/django/core/handlers/exception.py", line 55, in inner
    response = get_response(request)
               ^^^^^^^^^^^^^^^^^^^^^
  File "/home/zaffarelli/.virtualenvs/owod/lib/python3.11/site-packages/django/core/handlers/base.py", line 197, in _get_response
    response = wrapped_callback(request, *callback_args, **callback_kwargs)
               ^^^^^^^^^^^^^^^^^^^^^^^^^^^^^^^^^^^^^^^^^^^^^^^^^^^^^^^^^^^^
  File "/home/zaffarelli/.virtualenvs/owod/lib/python3.11/site-packages/django/views/decorators/csrf.py", line 56, in wrapper_view
    return view_func(*args, **kwargs)
           ^^^^^^^^^^^^^^^^^^^^^^^^^^
  File "/home/zaffarelli/Perso/github/wawwod/collector/views/base.py", line 129, in updown
    item.save()
  File "/home/zaffarelli/.virtualenvs/owod/lib/python3.11/site-packages/django/db/models/base.py", line 814, in save
    self.save_base(
  File "/home/zaffarelli/.virtualenvs/owod/lib/python3.11/site-packages/django/db/models/base.py", line 877, in save_base
    updated = self._save_table(
              ^^^^^^^^^^^^^^^^^
  File "/home/zaffarelli/.virtualenvs/owod/lib/python3.11/site-packages/django/db/models/base.py", line 990, in _save_table
    updated = self._do_update(
              ^^^^^^^^^^^^^^^^
  File "/home/zaffarelli/.virtualenvs/owod/lib/python3.11/site-packages/django/db/models/base.py", line 1054, in _do_update
    return filtered._update(values) > 0
           ^^^^^^^^^^^^^^^^^^^^^^^^
  File "/home/zaffarelli/.virtualenvs/owod/lib/python3.11/site-packages/django/db/models/query.py", line 1231, in _update
    return query.get_compiler(self.db).execute_sql(CURSOR)
           ^^^^^^^^^^^^^^^^^^^^^^^^^^^^^^^^^^^^^^^^^^^^^^^
  File "/home/zaffarelli/.virtualenvs/owod/lib/python3.11/site-packages/django/db/models/sql/compiler.py", line 1982, in execute_sql
    cursor = super().execute_sql(result_type)
             ^^^^^^^^^^^^^^^^^^^^^^^^^^^^^^^^
  File "/home/zaffarelli/.virtualenvs/owod/lib/python3.11/site-packages/django/db/models/sql/compiler.py", line 1560, in execute_sql
    cursor.execute(sql, params)
  File "/home/zaffarelli/.virtualenvs/owod/lib/python3.11/site-packages/django/db/backends/utils.py", line 102, in execute
    return super().execute(sql, params)
           ^^^^^^^^^^^^^^^^^^^^^^^^^^^^
  File "/home/zaffarelli/.virtualenvs/owod/lib/python3.11/site-packages/django/db/backends/utils.py", line 67, in execute
    return self._execute_with_wrappers(
           ^^^^^^^^^^^^^^^^^^^^^^^^^^^^
  File "/home/zaffarelli/.virtualenvs/owod/lib/python3.11/site-packages/django/db/backends/utils.py", line 80, in _execute_with_wrappers
    return executor(sql, params, many, context)
           ^^^^^^^^^^^^^^^^^^^^^^^^^^^^^^^^^^^^
  File "/home/zaffarelli/.virtualenvs/owod/lib/python3.11/site-packages/django/db/backends/utils.py", line 84, in _execute
    with self.db.wrap_database_errors:
  File "/home/zaffarelli/.virtualenvs/owod/lib/python3.11/site-packages/django/db/utils.py", line 91, in __exit__
    raise dj_exc_value.with_traceback(traceback) from exc_value
  File "/home/zaffarelli/.virtualenvs/owod/lib/python3.11/site-packages/django/db/backends/utils.py", line 89, in _execute
    return self.cursor.execute(sql, params)
           ^^^^^^^^^^^^^^^^^^^^^^^^^^^^^^^^
  File "/home/zaffarelli/.virtualenvs/owod/lib/python3.11/site-packages/django/db/backends/mysql/base.py", line 75, in execute
    return self.cursor.execute(query, args)
           ^^^^^^^^^^^^^^^^^^^^^^^^^^^^^^^^
  File "/home/zaffarelli/.virtualenvs/owod/lib64/python3.11/site-packages/MySQLdb/cursors.py", line 206, in execute
    res = self._query(query)
          ^^^^^^^^^^^^^^^^^^
  File "/home/zaffarelli/.virtualenvs/owod/lib64/python3.11/site-packages/MySQLdb/cursors.py", line 319, in _query
    db.query(q)
  File "/home/zaffarelli/.virtualenvs/owod/lib64/python3.11/site-packages/MySQLdb/connections.py", line 254, in query
    _mysql.connection.query(self, query)
django.db.utils.DataError: (1264, "Out of range value for column 'background8' at row 1")
[05/06 14:12:15] "POST /ajax/editable/updown/ HTTP/1.1" 500 25907
[05/06 14:32:53] "GET /static/collector/clans/blood_brothers.webp HTTP/1.1" 404 1861
[05/06 14:32:53] "GET /static/collector/clans/gargoyle.webp HTTP/1.1" 404 1843
[05/06 14:32:57] "GET /static/collector/clans/gargoyle.webp HTTP/1.1" 404 1843
[05/06 14:32:57] "GET /static/collector/clans/blood_brothers.webp HTTP/1.1" 404 1861
[07/06 01:59:56] "GET /static/storytelling/fonts/Lato-Regular.ttf HTTP/1.1" 404 1861
[07/06 02:48:58] "GET /static/storytelling/fonts/Lato-Regular.ttf HTTP/1.1" 404 1861
[07/06 02:53:16] "GET /static/storytelling/fonts/Lato-Regular.ttf HTTP/1.1" 404 1861
[07/06 02:54:08] "GET /static/storytelling/fonts/Lato-Regular.ttf HTTP/1.1" 404 1861
[07/06 02:59:06] Internal Server Error: /ajax/editable/updown/
Traceback (most recent call last):
  File "/home/zaffarelli/.virtualenvs/owod/lib/python3.11/site-packages/django/core/handlers/exception.py", line 55, in inner
    response = get_response(request)
               ^^^^^^^^^^^^^^^^^^^^^
  File "/home/zaffarelli/.virtualenvs/owod/lib/python3.11/site-packages/django/core/handlers/base.py", line 197, in _get_response
    response = wrapped_callback(request, *callback_args, **callback_kwargs)
               ^^^^^^^^^^^^^^^^^^^^^^^^^^^^^^^^^^^^^^^^^^^^^^^^^^^^^^^^^^^^
  File "/home/zaffarelli/.virtualenvs/owod/lib/python3.11/site-packages/django/views/decorators/csrf.py", line 56, in wrapper_view
    return view_func(*args, **kwargs)
           ^^^^^^^^^^^^^^^^^^^^^^^^^^
  File "/home/zaffarelli/Perso/github/wawwod/collector/views/base.py", line 123, in updown
    item = Creature.objects.get(rid=rid)
           ^^^^^^^^^^^^^^^^^^^^^^^^^^^^^
  File "/home/zaffarelli/.virtualenvs/owod/lib/python3.11/site-packages/django/db/models/manager.py", line 87, in manager_method
    return getattr(self.get_queryset(), name)(*args, **kwargs)
           ^^^^^^^^^^^^^^^^^^^^^^^^^^^^^^^^^^^^^^^^^^^^^^^^^^^
  File "/home/zaffarelli/.virtualenvs/owod/lib/python3.11/site-packages/django/db/models/query.py", line 637, in get
    raise self.model.DoesNotExist(
collector.models.creatures.Creature.DoesNotExist: Creature matching query does not exist.
[07/06 02:59:06] "POST /ajax/editable/updown/ HTTP/1.1" 500 21902
[07/06 02:59:07] Internal Server Error: /ajax/editable/updown/
Traceback (most recent call last):
  File "/home/zaffarelli/.virtualenvs/owod/lib/python3.11/site-packages/django/core/handlers/exception.py", line 55, in inner
    response = get_response(request)
               ^^^^^^^^^^^^^^^^^^^^^
  File "/home/zaffarelli/.virtualenvs/owod/lib/python3.11/site-packages/django/core/handlers/base.py", line 197, in _get_response
    response = wrapped_callback(request, *callback_args, **callback_kwargs)
               ^^^^^^^^^^^^^^^^^^^^^^^^^^^^^^^^^^^^^^^^^^^^^^^^^^^^^^^^^^^^
  File "/home/zaffarelli/.virtualenvs/owod/lib/python3.11/site-packages/django/views/decorators/csrf.py", line 56, in wrapper_view
    return view_func(*args, **kwargs)
           ^^^^^^^^^^^^^^^^^^^^^^^^^^
  File "/home/zaffarelli/Perso/github/wawwod/collector/views/base.py", line 123, in updown
    item = Creature.objects.get(rid=rid)
           ^^^^^^^^^^^^^^^^^^^^^^^^^^^^^
  File "/home/zaffarelli/.virtualenvs/owod/lib/python3.11/site-packages/django/db/models/manager.py", line 87, in manager_method
    return getattr(self.get_queryset(), name)(*args, **kwargs)
           ^^^^^^^^^^^^^^^^^^^^^^^^^^^^^^^^^^^^^^^^^^^^^^^^^^^
  File "/home/zaffarelli/.virtualenvs/owod/lib/python3.11/site-packages/django/db/models/query.py", line 637, in get
    raise self.model.DoesNotExist(
collector.models.creatures.Creature.DoesNotExist: Creature matching query does not exist.
[07/06 02:59:07] "POST /ajax/editable/updown/ HTTP/1.1" 500 21902
[07/06 02:59:10] Internal Server Error: /ajax/editable/updown/
Traceback (most recent call last):
  File "/home/zaffarelli/.virtualenvs/owod/lib/python3.11/site-packages/django/core/handlers/exception.py", line 55, in inner
    response = get_response(request)
               ^^^^^^^^^^^^^^^^^^^^^
  File "/home/zaffarelli/.virtualenvs/owod/lib/python3.11/site-packages/django/core/handlers/base.py", line 197, in _get_response
    response = wrapped_callback(request, *callback_args, **callback_kwargs)
               ^^^^^^^^^^^^^^^^^^^^^^^^^^^^^^^^^^^^^^^^^^^^^^^^^^^^^^^^^^^^
  File "/home/zaffarelli/.virtualenvs/owod/lib/python3.11/site-packages/django/views/decorators/csrf.py", line 56, in wrapper_view
    return view_func(*args, **kwargs)
           ^^^^^^^^^^^^^^^^^^^^^^^^^^
  File "/home/zaffarelli/Perso/github/wawwod/collector/views/base.py", line 123, in updown
    item = Creature.objects.get(rid=rid)
           ^^^^^^^^^^^^^^^^^^^^^^^^^^^^^
  File "/home/zaffarelli/.virtualenvs/owod/lib/python3.11/site-packages/django/db/models/manager.py", line 87, in manager_method
    return getattr(self.get_queryset(), name)(*args, **kwargs)
           ^^^^^^^^^^^^^^^^^^^^^^^^^^^^^^^^^^^^^^^^^^^^^^^^^^^
  File "/home/zaffarelli/.virtualenvs/owod/lib/python3.11/site-packages/django/db/models/query.py", line 637, in get
    raise self.model.DoesNotExist(
collector.models.creatures.Creature.DoesNotExist: Creature matching query does not exist.
[07/06 02:59:10] "POST /ajax/editable/updown/ HTTP/1.1" 500 21902
[07/06 02:59:10] Internal Server Error: /ajax/editable/updown/
Traceback (most recent call last):
  File "/home/zaffarelli/.virtualenvs/owod/lib/python3.11/site-packages/django/core/handlers/exception.py", line 55, in inner
    response = get_response(request)
               ^^^^^^^^^^^^^^^^^^^^^
  File "/home/zaffarelli/.virtualenvs/owod/lib/python3.11/site-packages/django/core/handlers/base.py", line 197, in _get_response
    response = wrapped_callback(request, *callback_args, **callback_kwargs)
               ^^^^^^^^^^^^^^^^^^^^^^^^^^^^^^^^^^^^^^^^^^^^^^^^^^^^^^^^^^^^
  File "/home/zaffarelli/.virtualenvs/owod/lib/python3.11/site-packages/django/views/decorators/csrf.py", line 56, in wrapper_view
    return view_func(*args, **kwargs)
           ^^^^^^^^^^^^^^^^^^^^^^^^^^
  File "/home/zaffarelli/Perso/github/wawwod/collector/views/base.py", line 123, in updown
    item = Creature.objects.get(rid=rid)
           ^^^^^^^^^^^^^^^^^^^^^^^^^^^^^
  File "/home/zaffarelli/.virtualenvs/owod/lib/python3.11/site-packages/django/db/models/manager.py", line 87, in manager_method
    return getattr(self.get_queryset(), name)(*args, **kwargs)
           ^^^^^^^^^^^^^^^^^^^^^^^^^^^^^^^^^^^^^^^^^^^^^^^^^^^
  File "/home/zaffarelli/.virtualenvs/owod/lib/python3.11/site-packages/django/db/models/query.py", line 637, in get
    raise self.model.DoesNotExist(
collector.models.creatures.Creature.DoesNotExist: Creature matching query does not exist.
[07/06 02:59:10] "POST /ajax/editable/updown/ HTTP/1.1" 500 21902
[07/06 02:59:11] Internal Server Error: /ajax/editable/updown/
Traceback (most recent call last):
  File "/home/zaffarelli/.virtualenvs/owod/lib/python3.11/site-packages/django/core/handlers/exception.py", line 55, in inner
    response = get_response(request)
               ^^^^^^^^^^^^^^^^^^^^^
  File "/home/zaffarelli/.virtualenvs/owod/lib/python3.11/site-packages/django/core/handlers/base.py", line 197, in _get_response
    response = wrapped_callback(request, *callback_args, **callback_kwargs)
               ^^^^^^^^^^^^^^^^^^^^^^^^^^^^^^^^^^^^^^^^^^^^^^^^^^^^^^^^^^^^
  File "/home/zaffarelli/.virtualenvs/owod/lib/python3.11/site-packages/django/views/decorators/csrf.py", line 56, in wrapper_view
    return view_func(*args, **kwargs)
           ^^^^^^^^^^^^^^^^^^^^^^^^^^
  File "/home/zaffarelli/Perso/github/wawwod/collector/views/base.py", line 123, in updown
    item = Creature.objects.get(rid=rid)
           ^^^^^^^^^^^^^^^^^^^^^^^^^^^^^
  File "/home/zaffarelli/.virtualenvs/owod/lib/python3.11/site-packages/django/db/models/manager.py", line 87, in manager_method
    return getattr(self.get_queryset(), name)(*args, **kwargs)
           ^^^^^^^^^^^^^^^^^^^^^^^^^^^^^^^^^^^^^^^^^^^^^^^^^^^
  File "/home/zaffarelli/.virtualenvs/owod/lib/python3.11/site-packages/django/db/models/query.py", line 637, in get
    raise self.model.DoesNotExist(
collector.models.creatures.Creature.DoesNotExist: Creature matching query does not exist.
[07/06 02:59:11] "POST /ajax/editable/updown/ HTTP/1.1" 500 21902
[07/06 02:59:12] Internal Server Error: /ajax/editable/updown/
Traceback (most recent call last):
  File "/home/zaffarelli/.virtualenvs/owod/lib/python3.11/site-packages/django/core/handlers/exception.py", line 55, in inner
    response = get_response(request)
               ^^^^^^^^^^^^^^^^^^^^^
  File "/home/zaffarelli/.virtualenvs/owod/lib/python3.11/site-packages/django/core/handlers/base.py", line 197, in _get_response
    response = wrapped_callback(request, *callback_args, **callback_kwargs)
               ^^^^^^^^^^^^^^^^^^^^^^^^^^^^^^^^^^^^^^^^^^^^^^^^^^^^^^^^^^^^
  File "/home/zaffarelli/.virtualenvs/owod/lib/python3.11/site-packages/django/views/decorators/csrf.py", line 56, in wrapper_view
    return view_func(*args, **kwargs)
           ^^^^^^^^^^^^^^^^^^^^^^^^^^
  File "/home/zaffarelli/Perso/github/wawwod/collector/views/base.py", line 123, in updown
    item = Creature.objects.get(rid=rid)
           ^^^^^^^^^^^^^^^^^^^^^^^^^^^^^
  File "/home/zaffarelli/.virtualenvs/owod/lib/python3.11/site-packages/django/db/models/manager.py", line 87, in manager_method
    return getattr(self.get_queryset(), name)(*args, **kwargs)
           ^^^^^^^^^^^^^^^^^^^^^^^^^^^^^^^^^^^^^^^^^^^^^^^^^^^
  File "/home/zaffarelli/.virtualenvs/owod/lib/python3.11/site-packages/django/db/models/query.py", line 637, in get
    raise self.model.DoesNotExist(
collector.models.creatures.Creature.DoesNotExist: Creature matching query does not exist.
[07/06 02:59:12] "POST /ajax/editable/updown/ HTTP/1.1" 500 21901
[07/06 02:59:13] Internal Server Error: /ajax/editable/updown/
Traceback (most recent call last):
  File "/home/zaffarelli/.virtualenvs/owod/lib/python3.11/site-packages/django/core/handlers/exception.py", line 55, in inner
    response = get_response(request)
               ^^^^^^^^^^^^^^^^^^^^^
  File "/home/zaffarelli/.virtualenvs/owod/lib/python3.11/site-packages/django/core/handlers/base.py", line 197, in _get_response
    response = wrapped_callback(request, *callback_args, **callback_kwargs)
               ^^^^^^^^^^^^^^^^^^^^^^^^^^^^^^^^^^^^^^^^^^^^^^^^^^^^^^^^^^^^
  File "/home/zaffarelli/.virtualenvs/owod/lib/python3.11/site-packages/django/views/decorators/csrf.py", line 56, in wrapper_view
    return view_func(*args, **kwargs)
           ^^^^^^^^^^^^^^^^^^^^^^^^^^
  File "/home/zaffarelli/Perso/github/wawwod/collector/views/base.py", line 123, in updown
    item = Creature.objects.get(rid=rid)
           ^^^^^^^^^^^^^^^^^^^^^^^^^^^^^
  File "/home/zaffarelli/.virtualenvs/owod/lib/python3.11/site-packages/django/db/models/manager.py", line 87, in manager_method
    return getattr(self.get_queryset(), name)(*args, **kwargs)
           ^^^^^^^^^^^^^^^^^^^^^^^^^^^^^^^^^^^^^^^^^^^^^^^^^^^
  File "/home/zaffarelli/.virtualenvs/owod/lib/python3.11/site-packages/django/db/models/query.py", line 637, in get
    raise self.model.DoesNotExist(
collector.models.creatures.Creature.DoesNotExist: Creature matching query does not exist.
[07/06 02:59:13] "POST /ajax/editable/updown/ HTTP/1.1" 500 21901
[07/06 02:59:40] Internal Server Error: /ajax/editable/updown/
Traceback (most recent call last):
  File "/home/zaffarelli/.virtualenvs/owod/lib/python3.11/site-packages/django/core/handlers/exception.py", line 55, in inner
    response = get_response(request)
               ^^^^^^^^^^^^^^^^^^^^^
  File "/home/zaffarelli/.virtualenvs/owod/lib/python3.11/site-packages/django/core/handlers/base.py", line 197, in _get_response
    response = wrapped_callback(request, *callback_args, **callback_kwargs)
               ^^^^^^^^^^^^^^^^^^^^^^^^^^^^^^^^^^^^^^^^^^^^^^^^^^^^^^^^^^^^
  File "/home/zaffarelli/.virtualenvs/owod/lib/python3.11/site-packages/django/views/decorators/csrf.py", line 56, in wrapper_view
    return view_func(*args, **kwargs)
           ^^^^^^^^^^^^^^^^^^^^^^^^^^
  File "/home/zaffarelli/Perso/github/wawwod/collector/views/base.py", line 123, in updown
    item = Creature.objects.get(rid=rid)
           ^^^^^^^^^^^^^^^^^^^^^^^^^^^^^
  File "/home/zaffarelli/.virtualenvs/owod/lib/python3.11/site-packages/django/db/models/manager.py", line 87, in manager_method
    return getattr(self.get_queryset(), name)(*args, **kwargs)
           ^^^^^^^^^^^^^^^^^^^^^^^^^^^^^^^^^^^^^^^^^^^^^^^^^^^
  File "/home/zaffarelli/.virtualenvs/owod/lib/python3.11/site-packages/django/db/models/query.py", line 637, in get
    raise self.model.DoesNotExist(
collector.models.creatures.Creature.DoesNotExist: Creature matching query does not exist.
[07/06 02:59:40] "POST /ajax/editable/updown/ HTTP/1.1" 500 21902
[07/06 02:59:42] Internal Server Error: /ajax/editable/updown/
Traceback (most recent call last):
  File "/home/zaffarelli/.virtualenvs/owod/lib/python3.11/site-packages/django/core/handlers/exception.py", line 55, in inner
    response = get_response(request)
               ^^^^^^^^^^^^^^^^^^^^^
  File "/home/zaffarelli/.virtualenvs/owod/lib/python3.11/site-packages/django/core/handlers/base.py", line 197, in _get_response
    response = wrapped_callback(request, *callback_args, **callback_kwargs)
               ^^^^^^^^^^^^^^^^^^^^^^^^^^^^^^^^^^^^^^^^^^^^^^^^^^^^^^^^^^^^
  File "/home/zaffarelli/.virtualenvs/owod/lib/python3.11/site-packages/django/views/decorators/csrf.py", line 56, in wrapper_view
    return view_func(*args, **kwargs)
           ^^^^^^^^^^^^^^^^^^^^^^^^^^
  File "/home/zaffarelli/Perso/github/wawwod/collector/views/base.py", line 123, in updown
    item = Creature.objects.get(rid=rid)
           ^^^^^^^^^^^^^^^^^^^^^^^^^^^^^
  File "/home/zaffarelli/.virtualenvs/owod/lib/python3.11/site-packages/django/db/models/manager.py", line 87, in manager_method
    return getattr(self.get_queryset(), name)(*args, **kwargs)
           ^^^^^^^^^^^^^^^^^^^^^^^^^^^^^^^^^^^^^^^^^^^^^^^^^^^
  File "/home/zaffarelli/.virtualenvs/owod/lib/python3.11/site-packages/django/db/models/query.py", line 637, in get
    raise self.model.DoesNotExist(
collector.models.creatures.Creature.DoesNotExist: Creature matching query does not exist.
[07/06 02:59:42] "POST /ajax/editable/updown/ HTTP/1.1" 500 21901
[07/06 02:59:44] Internal Server Error: /ajax/editable/updown/
Traceback (most recent call last):
  File "/home/zaffarelli/.virtualenvs/owod/lib/python3.11/site-packages/django/core/handlers/exception.py", line 55, in inner
    response = get_response(request)
               ^^^^^^^^^^^^^^^^^^^^^
  File "/home/zaffarelli/.virtualenvs/owod/lib/python3.11/site-packages/django/core/handlers/base.py", line 197, in _get_response
    response = wrapped_callback(request, *callback_args, **callback_kwargs)
               ^^^^^^^^^^^^^^^^^^^^^^^^^^^^^^^^^^^^^^^^^^^^^^^^^^^^^^^^^^^^
  File "/home/zaffarelli/.virtualenvs/owod/lib/python3.11/site-packages/django/views/decorators/csrf.py", line 56, in wrapper_view
    return view_func(*args, **kwargs)
           ^^^^^^^^^^^^^^^^^^^^^^^^^^
  File "/home/zaffarelli/Perso/github/wawwod/collector/views/base.py", line 123, in updown
    item = Creature.objects.get(rid=rid)
           ^^^^^^^^^^^^^^^^^^^^^^^^^^^^^
  File "/home/zaffarelli/.virtualenvs/owod/lib/python3.11/site-packages/django/db/models/manager.py", line 87, in manager_method
    return getattr(self.get_queryset(), name)(*args, **kwargs)
           ^^^^^^^^^^^^^^^^^^^^^^^^^^^^^^^^^^^^^^^^^^^^^^^^^^^
  File "/home/zaffarelli/.virtualenvs/owod/lib/python3.11/site-packages/django/db/models/query.py", line 637, in get
    raise self.model.DoesNotExist(
collector.models.creatures.Creature.DoesNotExist: Creature matching query does not exist.
[07/06 02:59:44] "POST /ajax/editable/updown/ HTTP/1.1" 500 21901
[07/06 03:01:06] Internal Server Error: /ajax/editable/updown/
Traceback (most recent call last):
  File "/home/zaffarelli/.virtualenvs/owod/lib/python3.11/site-packages/django/core/handlers/exception.py", line 55, in inner
    response = get_response(request)
               ^^^^^^^^^^^^^^^^^^^^^
  File "/home/zaffarelli/.virtualenvs/owod/lib/python3.11/site-packages/django/core/handlers/base.py", line 197, in _get_response
    response = wrapped_callback(request, *callback_args, **callback_kwargs)
               ^^^^^^^^^^^^^^^^^^^^^^^^^^^^^^^^^^^^^^^^^^^^^^^^^^^^^^^^^^^^
  File "/home/zaffarelli/.virtualenvs/owod/lib/python3.11/site-packages/django/views/decorators/csrf.py", line 56, in wrapper_view
    return view_func(*args, **kwargs)
           ^^^^^^^^^^^^^^^^^^^^^^^^^^
  File "/home/zaffarelli/Perso/github/wawwod/collector/views/base.py", line 123, in updown
    item = Creature.objects.get(rid=rid)
           ^^^^^^^^^^^^^^^^^^^^^^^^^^^^^
  File "/home/zaffarelli/.virtualenvs/owod/lib/python3.11/site-packages/django/db/models/manager.py", line 87, in manager_method
    return getattr(self.get_queryset(), name)(*args, **kwargs)
           ^^^^^^^^^^^^^^^^^^^^^^^^^^^^^^^^^^^^^^^^^^^^^^^^^^^
  File "/home/zaffarelli/.virtualenvs/owod/lib/python3.11/site-packages/django/db/models/query.py", line 637, in get
    raise self.model.DoesNotExist(
collector.models.creatures.Creature.DoesNotExist: Creature matching query does not exist.
[07/06 03:01:06] "POST /ajax/editable/updown/ HTTP/1.1" 500 21902
[07/06 03:04:11] "GET /static/storytelling/fonts/Lato-Regular.ttf HTTP/1.1" 404 1861
[07/06 03:04:41] "GET /static/storytelling/fonts/Lato-Regular.ttf HTTP/1.1" 404 1861
[07/06 04:09:27] Not Found: /favicon.ico
[07/06 04:09:27] "GET /favicon.ico HTTP/1.1" 404 8687
[08/06 00:49:09] Not Found: /favicon.ico
[11/06 17:35:52] Not Found: /favicon.ico
[11/06 17:41:37] Internal Server Error: /admin/storytelling/district/
Traceback (most recent call last):
  File "/home/zaffarelli/.virtualenvs/owod/lib/python3.11/site-packages/django/db/backends/utils.py", line 89, in _execute
    return self.cursor.execute(sql, params)
           ^^^^^^^^^^^^^^^^^^^^^^^^^^^^^^^^
  File "/home/zaffarelli/.virtualenvs/owod/lib/python3.11/site-packages/django/db/backends/mysql/base.py", line 75, in execute
    return self.cursor.execute(query, args)
           ^^^^^^^^^^^^^^^^^^^^^^^^^^^^^^^^
  File "/home/zaffarelli/.virtualenvs/owod/lib64/python3.11/site-packages/MySQLdb/cursors.py", line 206, in execute
    res = self._query(query)
          ^^^^^^^^^^^^^^^^^^
  File "/home/zaffarelli/.virtualenvs/owod/lib64/python3.11/site-packages/MySQLdb/cursors.py", line 319, in _query
    db.query(q)
  File "/home/zaffarelli/.virtualenvs/owod/lib64/python3.11/site-packages/MySQLdb/connections.py", line 254, in query
    _mysql.connection.query(self, query)
MySQLdb.DataError: (1264, "Out of range value for column 'population' at row 1")

The above exception was the direct cause of the following exception:

Traceback (most recent call last):
  File "/home/zaffarelli/.virtualenvs/owod/lib/python3.11/site-packages/django/core/handlers/exception.py", line 55, in inner
    response = get_response(request)
               ^^^^^^^^^^^^^^^^^^^^^
  File "/home/zaffarelli/.virtualenvs/owod/lib/python3.11/site-packages/django/core/handlers/base.py", line 197, in _get_response
    response = wrapped_callback(request, *callback_args, **callback_kwargs)
               ^^^^^^^^^^^^^^^^^^^^^^^^^^^^^^^^^^^^^^^^^^^^^^^^^^^^^^^^^^^^
  File "/home/zaffarelli/.virtualenvs/owod/lib/python3.11/site-packages/django/contrib/admin/options.py", line 688, in wrapper
    return self.admin_site.admin_view(view)(*args, **kwargs)
           ^^^^^^^^^^^^^^^^^^^^^^^^^^^^^^^^^^^^^^^^^^^^^^^^^
  File "/home/zaffarelli/.virtualenvs/owod/lib/python3.11/site-packages/django/utils/decorators.py", line 134, in _wrapper_view
    response = view_func(request, *args, **kwargs)
               ^^^^^^^^^^^^^^^^^^^^^^^^^^^^^^^^^^^
  File "/home/zaffarelli/.virtualenvs/owod/lib/python3.11/site-packages/django/views/decorators/cache.py", line 62, in _wrapper_view_func
    response = view_func(request, *args, **kwargs)
               ^^^^^^^^^^^^^^^^^^^^^^^^^^^^^^^^^^^
  File "/home/zaffarelli/.virtualenvs/owod/lib/python3.11/site-packages/django/contrib/admin/sites.py", line 242, in inner
    return view(request, *args, **kwargs)
           ^^^^^^^^^^^^^^^^^^^^^^^^^^^^^^
  File "/home/zaffarelli/.virtualenvs/owod/lib/python3.11/site-packages/django/utils/decorators.py", line 46, in _wrapper
    return bound_method(*args, **kwargs)
           ^^^^^^^^^^^^^^^^^^^^^^^^^^^^^
  File "/home/zaffarelli/.virtualenvs/owod/lib/python3.11/site-packages/django/utils/decorators.py", line 134, in _wrapper_view
    response = view_func(request, *args, **kwargs)
               ^^^^^^^^^^^^^^^^^^^^^^^^^^^^^^^^^^^
  File "/home/zaffarelli/.virtualenvs/owod/lib/python3.11/site-packages/django/contrib/admin/options.py", line 1959, in changelist_view
    response = self.response_action(
               ^^^^^^^^^^^^^^^^^^^^^
  File "/home/zaffarelli/.virtualenvs/owod/lib/python3.11/site-packages/django/contrib/admin/options.py", line 1593, in response_action
    response = func(self, request, queryset)
               ^^^^^^^^^^^^^^^^^^^^^^^^^^^^^
  File "/home/zaffarelli/Perso/github/wawwod/storytelling/models/districts.py", line 177, in repopulate
    district.save()
  File "/home/zaffarelli/.virtualenvs/owod/lib/python3.11/site-packages/django/db/models/base.py", line 814, in save
    self.save_base(
  File "/home/zaffarelli/.virtualenvs/owod/lib/python3.11/site-packages/django/db/models/base.py", line 877, in save_base
    updated = self._save_table(
              ^^^^^^^^^^^^^^^^^
  File "/home/zaffarelli/.virtualenvs/owod/lib/python3.11/site-packages/django/db/models/base.py", line 990, in _save_table
    updated = self._do_update(
              ^^^^^^^^^^^^^^^^
  File "/home/zaffarelli/.virtualenvs/owod/lib/python3.11/site-packages/django/db/models/base.py", line 1054, in _do_update
    return filtered._update(values) > 0
           ^^^^^^^^^^^^^^^^^^^^^^^^
  File "/home/zaffarelli/.virtualenvs/owod/lib/python3.11/site-packages/django/db/models/query.py", line 1231, in _update
    return query.get_compiler(self.db).execute_sql(CURSOR)
           ^^^^^^^^^^^^^^^^^^^^^^^^^^^^^^^^^^^^^^^^^^^^^^^
  File "/home/zaffarelli/.virtualenvs/owod/lib/python3.11/site-packages/django/db/models/sql/compiler.py", line 1982, in execute_sql
    cursor = super().execute_sql(result_type)
             ^^^^^^^^^^^^^^^^^^^^^^^^^^^^^^^^
  File "/home/zaffarelli/.virtualenvs/owod/lib/python3.11/site-packages/django/db/models/sql/compiler.py", line 1560, in execute_sql
    cursor.execute(sql, params)
  File "/home/zaffarelli/.virtualenvs/owod/lib/python3.11/site-packages/django/db/backends/utils.py", line 102, in execute
    return super().execute(sql, params)
           ^^^^^^^^^^^^^^^^^^^^^^^^^^^^
  File "/home/zaffarelli/.virtualenvs/owod/lib/python3.11/site-packages/django/db/backends/utils.py", line 67, in execute
    return self._execute_with_wrappers(
           ^^^^^^^^^^^^^^^^^^^^^^^^^^^^
  File "/home/zaffarelli/.virtualenvs/owod/lib/python3.11/site-packages/django/db/backends/utils.py", line 80, in _execute_with_wrappers
    return executor(sql, params, many, context)
           ^^^^^^^^^^^^^^^^^^^^^^^^^^^^^^^^^^^^
  File "/home/zaffarelli/.virtualenvs/owod/lib/python3.11/site-packages/django/db/backends/utils.py", line 84, in _execute
    with self.db.wrap_database_errors:
  File "/home/zaffarelli/.virtualenvs/owod/lib/python3.11/site-packages/django/db/utils.py", line 91, in __exit__
    raise dj_exc_value.with_traceback(traceback) from exc_value
  File "/home/zaffarelli/.virtualenvs/owod/lib/python3.11/site-packages/django/db/backends/utils.py", line 89, in _execute
    return self.cursor.execute(sql, params)
           ^^^^^^^^^^^^^^^^^^^^^^^^^^^^^^^^
  File "/home/zaffarelli/.virtualenvs/owod/lib/python3.11/site-packages/django/db/backends/mysql/base.py", line 75, in execute
    return self.cursor.execute(query, args)
           ^^^^^^^^^^^^^^^^^^^^^^^^^^^^^^^^
  File "/home/zaffarelli/.virtualenvs/owod/lib64/python3.11/site-packages/MySQLdb/cursors.py", line 206, in execute
    res = self._query(query)
          ^^^^^^^^^^^^^^^^^^
  File "/home/zaffarelli/.virtualenvs/owod/lib64/python3.11/site-packages/MySQLdb/cursors.py", line 319, in _query
    db.query(q)
  File "/home/zaffarelli/.virtualenvs/owod/lib64/python3.11/site-packages/MySQLdb/connections.py", line 254, in query
    _mysql.connection.query(self, query)
django.db.utils.DataError: (1264, "Out of range value for column 'population' at row 1")
[11/06 17:41:37] "POST /admin/storytelling/district/ HTTP/1.1" 500 314267
[11/06 17:41:56] Internal Server Error: /admin/storytelling/district/
Traceback (most recent call last):
  File "/home/zaffarelli/.virtualenvs/owod/lib/python3.11/site-packages/django/db/backends/utils.py", line 89, in _execute
    return self.cursor.execute(sql, params)
           ^^^^^^^^^^^^^^^^^^^^^^^^^^^^^^^^
  File "/home/zaffarelli/.virtualenvs/owod/lib/python3.11/site-packages/django/db/backends/mysql/base.py", line 75, in execute
    return self.cursor.execute(query, args)
           ^^^^^^^^^^^^^^^^^^^^^^^^^^^^^^^^
  File "/home/zaffarelli/.virtualenvs/owod/lib64/python3.11/site-packages/MySQLdb/cursors.py", line 206, in execute
    res = self._query(query)
          ^^^^^^^^^^^^^^^^^^
  File "/home/zaffarelli/.virtualenvs/owod/lib64/python3.11/site-packages/MySQLdb/cursors.py", line 319, in _query
    db.query(q)
  File "/home/zaffarelli/.virtualenvs/owod/lib64/python3.11/site-packages/MySQLdb/connections.py", line 254, in query
    _mysql.connection.query(self, query)
MySQLdb.DataError: (1264, "Out of range value for column 'population' at row 1")

The above exception was the direct cause of the following exception:

Traceback (most recent call last):
  File "/home/zaffarelli/.virtualenvs/owod/lib/python3.11/site-packages/django/core/handlers/exception.py", line 55, in inner
    response = get_response(request)
               ^^^^^^^^^^^^^^^^^^^^^
  File "/home/zaffarelli/.virtualenvs/owod/lib/python3.11/site-packages/django/core/handlers/base.py", line 197, in _get_response
    response = wrapped_callback(request, *callback_args, **callback_kwargs)
               ^^^^^^^^^^^^^^^^^^^^^^^^^^^^^^^^^^^^^^^^^^^^^^^^^^^^^^^^^^^^
  File "/home/zaffarelli/.virtualenvs/owod/lib/python3.11/site-packages/django/contrib/admin/options.py", line 688, in wrapper
    return self.admin_site.admin_view(view)(*args, **kwargs)
           ^^^^^^^^^^^^^^^^^^^^^^^^^^^^^^^^^^^^^^^^^^^^^^^^^
  File "/home/zaffarelli/.virtualenvs/owod/lib/python3.11/site-packages/django/utils/decorators.py", line 134, in _wrapper_view
    response = view_func(request, *args, **kwargs)
               ^^^^^^^^^^^^^^^^^^^^^^^^^^^^^^^^^^^
  File "/home/zaffarelli/.virtualenvs/owod/lib/python3.11/site-packages/django/views/decorators/cache.py", line 62, in _wrapper_view_func
    response = view_func(request, *args, **kwargs)
               ^^^^^^^^^^^^^^^^^^^^^^^^^^^^^^^^^^^
  File "/home/zaffarelli/.virtualenvs/owod/lib/python3.11/site-packages/django/contrib/admin/sites.py", line 242, in inner
    return view(request, *args, **kwargs)
           ^^^^^^^^^^^^^^^^^^^^^^^^^^^^^^
  File "/home/zaffarelli/.virtualenvs/owod/lib/python3.11/site-packages/django/utils/decorators.py", line 46, in _wrapper
    return bound_method(*args, **kwargs)
           ^^^^^^^^^^^^^^^^^^^^^^^^^^^^^
  File "/home/zaffarelli/.virtualenvs/owod/lib/python3.11/site-packages/django/utils/decorators.py", line 134, in _wrapper_view
    response = view_func(request, *args, **kwargs)
               ^^^^^^^^^^^^^^^^^^^^^^^^^^^^^^^^^^^
  File "/home/zaffarelli/.virtualenvs/owod/lib/python3.11/site-packages/django/contrib/admin/options.py", line 1959, in changelist_view
    response = self.response_action(
               ^^^^^^^^^^^^^^^^^^^^^
  File "/home/zaffarelli/.virtualenvs/owod/lib/python3.11/site-packages/django/contrib/admin/options.py", line 1593, in response_action
    response = func(self, request, queryset)
               ^^^^^^^^^^^^^^^^^^^^^^^^^^^^^
  File "/home/zaffarelli/Perso/github/wawwod/storytelling/models/districts.py", line 177, in repopulate
    district.save()
  File "/home/zaffarelli/.virtualenvs/owod/lib/python3.11/site-packages/django/db/models/base.py", line 814, in save
    self.save_base(
  File "/home/zaffarelli/.virtualenvs/owod/lib/python3.11/site-packages/django/db/models/base.py", line 877, in save_base
    updated = self._save_table(
              ^^^^^^^^^^^^^^^^^
  File "/home/zaffarelli/.virtualenvs/owod/lib/python3.11/site-packages/django/db/models/base.py", line 990, in _save_table
    updated = self._do_update(
              ^^^^^^^^^^^^^^^^
  File "/home/zaffarelli/.virtualenvs/owod/lib/python3.11/site-packages/django/db/models/base.py", line 1054, in _do_update
    return filtered._update(values) > 0
           ^^^^^^^^^^^^^^^^^^^^^^^^
  File "/home/zaffarelli/.virtualenvs/owod/lib/python3.11/site-packages/django/db/models/query.py", line 1231, in _update
    return query.get_compiler(self.db).execute_sql(CURSOR)
           ^^^^^^^^^^^^^^^^^^^^^^^^^^^^^^^^^^^^^^^^^^^^^^^
  File "/home/zaffarelli/.virtualenvs/owod/lib/python3.11/site-packages/django/db/models/sql/compiler.py", line 1982, in execute_sql
    cursor = super().execute_sql(result_type)
             ^^^^^^^^^^^^^^^^^^^^^^^^^^^^^^^^
  File "/home/zaffarelli/.virtualenvs/owod/lib/python3.11/site-packages/django/db/models/sql/compiler.py", line 1560, in execute_sql
    cursor.execute(sql, params)
  File "/home/zaffarelli/.virtualenvs/owod/lib/python3.11/site-packages/django/db/backends/utils.py", line 102, in execute
    return super().execute(sql, params)
           ^^^^^^^^^^^^^^^^^^^^^^^^^^^^
  File "/home/zaffarelli/.virtualenvs/owod/lib/python3.11/site-packages/django/db/backends/utils.py", line 67, in execute
    return self._execute_with_wrappers(
           ^^^^^^^^^^^^^^^^^^^^^^^^^^^^
  File "/home/zaffarelli/.virtualenvs/owod/lib/python3.11/site-packages/django/db/backends/utils.py", line 80, in _execute_with_wrappers
    return executor(sql, params, many, context)
           ^^^^^^^^^^^^^^^^^^^^^^^^^^^^^^^^^^^^
  File "/home/zaffarelli/.virtualenvs/owod/lib/python3.11/site-packages/django/db/backends/utils.py", line 84, in _execute
    with self.db.wrap_database_errors:
  File "/home/zaffarelli/.virtualenvs/owod/lib/python3.11/site-packages/django/db/utils.py", line 91, in __exit__
    raise dj_exc_value.with_traceback(traceback) from exc_value
  File "/home/zaffarelli/.virtualenvs/owod/lib/python3.11/site-packages/django/db/backends/utils.py", line 89, in _execute
    return self.cursor.execute(sql, params)
           ^^^^^^^^^^^^^^^^^^^^^^^^^^^^^^^^
  File "/home/zaffarelli/.virtualenvs/owod/lib/python3.11/site-packages/django/db/backends/mysql/base.py", line 75, in execute
    return self.cursor.execute(query, args)
           ^^^^^^^^^^^^^^^^^^^^^^^^^^^^^^^^
  File "/home/zaffarelli/.virtualenvs/owod/lib64/python3.11/site-packages/MySQLdb/cursors.py", line 206, in execute
    res = self._query(query)
          ^^^^^^^^^^^^^^^^^^
  File "/home/zaffarelli/.virtualenvs/owod/lib64/python3.11/site-packages/MySQLdb/cursors.py", line 319, in _query
    db.query(q)
  File "/home/zaffarelli/.virtualenvs/owod/lib64/python3.11/site-packages/MySQLdb/connections.py", line 254, in query
    _mysql.connection.query(self, query)
django.db.utils.DataError: (1264, "Out of range value for column 'population' at row 1")
[11/06 17:41:56] "POST /admin/storytelling/district/?city__id__exact=2 HTTP/1.1" 500 314832
[11/06 17:44:58] Internal Server Error: /admin/storytelling/district/
Traceback (most recent call last):
  File "/home/zaffarelli/.virtualenvs/owod/lib/python3.11/site-packages/django/db/backends/utils.py", line 89, in _execute
    return self.cursor.execute(sql, params)
           ^^^^^^^^^^^^^^^^^^^^^^^^^^^^^^^^
  File "/home/zaffarelli/.virtualenvs/owod/lib/python3.11/site-packages/django/db/backends/mysql/base.py", line 75, in execute
    return self.cursor.execute(query, args)
           ^^^^^^^^^^^^^^^^^^^^^^^^^^^^^^^^
  File "/home/zaffarelli/.virtualenvs/owod/lib64/python3.11/site-packages/MySQLdb/cursors.py", line 206, in execute
    res = self._query(query)
          ^^^^^^^^^^^^^^^^^^
  File "/home/zaffarelli/.virtualenvs/owod/lib64/python3.11/site-packages/MySQLdb/cursors.py", line 319, in _query
    db.query(q)
  File "/home/zaffarelli/.virtualenvs/owod/lib64/python3.11/site-packages/MySQLdb/connections.py", line 254, in query
    _mysql.connection.query(self, query)
MySQLdb.DataError: (1264, "Out of range value for column 'population' at row 1")

The above exception was the direct cause of the following exception:

Traceback (most recent call last):
  File "/home/zaffarelli/.virtualenvs/owod/lib/python3.11/site-packages/django/core/handlers/exception.py", line 55, in inner
    response = get_response(request)
               ^^^^^^^^^^^^^^^^^^^^^
  File "/home/zaffarelli/.virtualenvs/owod/lib/python3.11/site-packages/django/core/handlers/base.py", line 197, in _get_response
    response = wrapped_callback(request, *callback_args, **callback_kwargs)
               ^^^^^^^^^^^^^^^^^^^^^^^^^^^^^^^^^^^^^^^^^^^^^^^^^^^^^^^^^^^^
  File "/home/zaffarelli/.virtualenvs/owod/lib/python3.11/site-packages/django/contrib/admin/options.py", line 688, in wrapper
    return self.admin_site.admin_view(view)(*args, **kwargs)
           ^^^^^^^^^^^^^^^^^^^^^^^^^^^^^^^^^^^^^^^^^^^^^^^^^
  File "/home/zaffarelli/.virtualenvs/owod/lib/python3.11/site-packages/django/utils/decorators.py", line 134, in _wrapper_view
    response = view_func(request, *args, **kwargs)
               ^^^^^^^^^^^^^^^^^^^^^^^^^^^^^^^^^^^
  File "/home/zaffarelli/.virtualenvs/owod/lib/python3.11/site-packages/django/views/decorators/cache.py", line 62, in _wrapper_view_func
    response = view_func(request, *args, **kwargs)
               ^^^^^^^^^^^^^^^^^^^^^^^^^^^^^^^^^^^
  File "/home/zaffarelli/.virtualenvs/owod/lib/python3.11/site-packages/django/contrib/admin/sites.py", line 242, in inner
    return view(request, *args, **kwargs)
           ^^^^^^^^^^^^^^^^^^^^^^^^^^^^^^
  File "/home/zaffarelli/.virtualenvs/owod/lib/python3.11/site-packages/django/utils/decorators.py", line 46, in _wrapper
    return bound_method(*args, **kwargs)
           ^^^^^^^^^^^^^^^^^^^^^^^^^^^^^
  File "/home/zaffarelli/.virtualenvs/owod/lib/python3.11/site-packages/django/utils/decorators.py", line 134, in _wrapper_view
    response = view_func(request, *args, **kwargs)
               ^^^^^^^^^^^^^^^^^^^^^^^^^^^^^^^^^^^
  File "/home/zaffarelli/.virtualenvs/owod/lib/python3.11/site-packages/django/contrib/admin/options.py", line 1959, in changelist_view
    response = self.response_action(
               ^^^^^^^^^^^^^^^^^^^^^
  File "/home/zaffarelli/.virtualenvs/owod/lib/python3.11/site-packages/django/contrib/admin/options.py", line 1593, in response_action
    response = func(self, request, queryset)
               ^^^^^^^^^^^^^^^^^^^^^^^^^^^^^
  File "/home/zaffarelli/Perso/github/wawwod/storytelling/models/districts.py", line 177, in repopulate
    district.save()
  File "/home/zaffarelli/.virtualenvs/owod/lib/python3.11/site-packages/django/db/models/base.py", line 814, in save
    self.save_base(
  File "/home/zaffarelli/.virtualenvs/owod/lib/python3.11/site-packages/django/db/models/base.py", line 877, in save_base
    updated = self._save_table(
              ^^^^^^^^^^^^^^^^^
  File "/home/zaffarelli/.virtualenvs/owod/lib/python3.11/site-packages/django/db/models/base.py", line 990, in _save_table
    updated = self._do_update(
              ^^^^^^^^^^^^^^^^
  File "/home/zaffarelli/.virtualenvs/owod/lib/python3.11/site-packages/django/db/models/base.py", line 1054, in _do_update
    return filtered._update(values) > 0
           ^^^^^^^^^^^^^^^^^^^^^^^^
  File "/home/zaffarelli/.virtualenvs/owod/lib/python3.11/site-packages/django/db/models/query.py", line 1231, in _update
    return query.get_compiler(self.db).execute_sql(CURSOR)
           ^^^^^^^^^^^^^^^^^^^^^^^^^^^^^^^^^^^^^^^^^^^^^^^
  File "/home/zaffarelli/.virtualenvs/owod/lib/python3.11/site-packages/django/db/models/sql/compiler.py", line 1982, in execute_sql
    cursor = super().execute_sql(result_type)
             ^^^^^^^^^^^^^^^^^^^^^^^^^^^^^^^^
  File "/home/zaffarelli/.virtualenvs/owod/lib/python3.11/site-packages/django/db/models/sql/compiler.py", line 1560, in execute_sql
    cursor.execute(sql, params)
  File "/home/zaffarelli/.virtualenvs/owod/lib/python3.11/site-packages/django/db/backends/utils.py", line 102, in execute
    return super().execute(sql, params)
           ^^^^^^^^^^^^^^^^^^^^^^^^^^^^
  File "/home/zaffarelli/.virtualenvs/owod/lib/python3.11/site-packages/django/db/backends/utils.py", line 67, in execute
    return self._execute_with_wrappers(
           ^^^^^^^^^^^^^^^^^^^^^^^^^^^^
  File "/home/zaffarelli/.virtualenvs/owod/lib/python3.11/site-packages/django/db/backends/utils.py", line 80, in _execute_with_wrappers
    return executor(sql, params, many, context)
           ^^^^^^^^^^^^^^^^^^^^^^^^^^^^^^^^^^^^
  File "/home/zaffarelli/.virtualenvs/owod/lib/python3.11/site-packages/django/db/backends/utils.py", line 84, in _execute
    with self.db.wrap_database_errors:
  File "/home/zaffarelli/.virtualenvs/owod/lib/python3.11/site-packages/django/db/utils.py", line 91, in __exit__
    raise dj_exc_value.with_traceback(traceback) from exc_value
  File "/home/zaffarelli/.virtualenvs/owod/lib/python3.11/site-packages/django/db/backends/utils.py", line 89, in _execute
    return self.cursor.execute(sql, params)
           ^^^^^^^^^^^^^^^^^^^^^^^^^^^^^^^^
  File "/home/zaffarelli/.virtualenvs/owod/lib/python3.11/site-packages/django/db/backends/mysql/base.py", line 75, in execute
    return self.cursor.execute(query, args)
           ^^^^^^^^^^^^^^^^^^^^^^^^^^^^^^^^
  File "/home/zaffarelli/.virtualenvs/owod/lib64/python3.11/site-packages/MySQLdb/cursors.py", line 206, in execute
    res = self._query(query)
          ^^^^^^^^^^^^^^^^^^
  File "/home/zaffarelli/.virtualenvs/owod/lib64/python3.11/site-packages/MySQLdb/cursors.py", line 319, in _query
    db.query(q)
  File "/home/zaffarelli/.virtualenvs/owod/lib64/python3.11/site-packages/MySQLdb/connections.py", line 254, in query
    _mysql.connection.query(self, query)
django.db.utils.DataError: (1264, "Out of range value for column 'population' at row 1")
[11/06 17:44:58] "POST /admin/storytelling/district/ HTTP/1.1" 500 318430
[12/06 15:42:01] Not Found: /favicon.ico
[12/06 15:42:13] Not Found: /favicon.ico
[12/06 15:42:30] Not Found: /favicon.ico
[12/06 15:42:46] Not Found: /favicon.ico
[12/06 15:42:50] Not Found: /favicon.ico
[12/06 15:43:50] Not Found: /favicon.ico
[12/06 15:43:53] Not Found: /favicon.ico
[12/06 15:44:39] Not Found: /favicon.ico
[12/06 15:45:08] "GET /static/collector/tribes/s.webp HTTP/1.1" 404 1825
[12/06 15:45:09] "GET /static/storytelling/fonts/Lato-Regular.ttf HTTP/1.1" 404 1861
[12/06 15:48:21] Not Found: /favicon.ico
[12/06 15:48:24] Not Found: /favicon.ico
[12/06 15:48:59] Not Found: /favicon.ico
[12/06 15:49:12] Internal Server Error: /admin/collector/creature/775/change/
Traceback (most recent call last):
  File "/home/zaffarelli/.virtualenvs/owod/lib/python3.11/site-packages/django/core/handlers/exception.py", line 55, in inner
    response = get_response(request)
               ^^^^^^^^^^^^^^^^^^^^^
  File "/home/zaffarelli/.virtualenvs/owod/lib/python3.11/site-packages/django/core/handlers/base.py", line 197, in _get_response
    response = wrapped_callback(request, *callback_args, **callback_kwargs)
               ^^^^^^^^^^^^^^^^^^^^^^^^^^^^^^^^^^^^^^^^^^^^^^^^^^^^^^^^^^^^
  File "/home/zaffarelli/.virtualenvs/owod/lib/python3.11/site-packages/django/contrib/admin/options.py", line 688, in wrapper
    return self.admin_site.admin_view(view)(*args, **kwargs)
           ^^^^^^^^^^^^^^^^^^^^^^^^^^^^^^^^^^^^^^^^^^^^^^^^^
  File "/home/zaffarelli/.virtualenvs/owod/lib/python3.11/site-packages/django/utils/decorators.py", line 134, in _wrapper_view
    response = view_func(request, *args, **kwargs)
               ^^^^^^^^^^^^^^^^^^^^^^^^^^^^^^^^^^^
  File "/home/zaffarelli/.virtualenvs/owod/lib/python3.11/site-packages/django/views/decorators/cache.py", line 62, in _wrapper_view_func
    response = view_func(request, *args, **kwargs)
               ^^^^^^^^^^^^^^^^^^^^^^^^^^^^^^^^^^^
  File "/home/zaffarelli/.virtualenvs/owod/lib/python3.11/site-packages/django/contrib/admin/sites.py", line 242, in inner
    return view(request, *args, **kwargs)
           ^^^^^^^^^^^^^^^^^^^^^^^^^^^^^^
  File "/home/zaffarelli/.virtualenvs/owod/lib/python3.11/site-packages/django/contrib/admin/options.py", line 1889, in change_view
    return self.changeform_view(request, object_id, form_url, extra_context)
           ^^^^^^^^^^^^^^^^^^^^^^^^^^^^^^^^^^^^^^^^^^^^^^^^^^^^^^^^^^^^^^^^^
  File "/home/zaffarelli/.virtualenvs/owod/lib/python3.11/site-packages/django/utils/decorators.py", line 46, in _wrapper
    return bound_method(*args, **kwargs)
           ^^^^^^^^^^^^^^^^^^^^^^^^^^^^^
  File "/home/zaffarelli/.virtualenvs/owod/lib/python3.11/site-packages/django/utils/decorators.py", line 134, in _wrapper_view
    response = view_func(request, *args, **kwargs)
               ^^^^^^^^^^^^^^^^^^^^^^^^^^^^^^^^^^^
  File "/home/zaffarelli/.virtualenvs/owod/lib/python3.11/site-packages/django/contrib/admin/options.py", line 1747, in changeform_view
    return self._changeform_view(request, object_id, form_url, extra_context)
           ^^^^^^^^^^^^^^^^^^^^^^^^^^^^^^^^^^^^^^^^^^^^^^^^^^^^^^^^^^^^^^^^^^
  File "/home/zaffarelli/.virtualenvs/owod/lib/python3.11/site-packages/django/contrib/admin/options.py", line 1798, in _changeform_view
    self.save_model(request, new_object, form, not add)
  File "/home/zaffarelli/.virtualenvs/owod/lib/python3.11/site-packages/django/contrib/admin/options.py", line 1227, in save_model
    obj.save()
  File "/home/zaffarelli/.virtualenvs/owod/lib/python3.11/site-packages/django/db/models/base.py", line 814, in save
    self.save_base(
  File "/home/zaffarelli/.virtualenvs/owod/lib/python3.11/site-packages/django/db/models/base.py", line 861, in save_base
    pre_save.send(
  File "/home/zaffarelli/.virtualenvs/owod/lib/python3.11/site-packages/django/dispatch/dispatcher.py", line 176, in send
    return [
           ^
  File "/home/zaffarelli/.virtualenvs/owod/lib/python3.11/site-packages/django/dispatch/dispatcher.py", line 177, in <listcomp>
    (receiver, receiver(signal=self, sender=sender, **named))
               ^^^^^^^^^^^^^^^^^^^^^^^^^^^^^^^^^^^^^^^^^^^^^
  File "/home/zaffarelli/Perso/github/wawwod/collector/signals/creatures.py", line 18, in update_creature
    instance.fix()
  File "/home/zaffarelli/Perso/github/wawwod/collector/models/creatures.py", line 691, in fix
    self.fix_garou()
  File "/home/zaffarelli/Perso/github/wawwod/collector/models/creatures.py", line 656, in fix_garou
    self.expectedfreebies = self.freebies_per_mortal_age + expected_freebies_by_rank[self.rank - 1]
                                                                                     ~~~~~~~~~~^~~
TypeError: unsupported operand type(s) for -: 'str' and 'int'
[12/06 15:49:12] "POST /admin/collector/creature/775/change/?_changelist_filters=adventure__name__exact%3DThe%2BWeeping%2BTree HTTP/1.1" 500 193358
[12/06 15:49:12] Not Found: /favicon.ico
[12/06 15:49:43] Internal Server Error: /admin/collector/creature/775/change/
Traceback (most recent call last):
  File "/home/zaffarelli/.virtualenvs/owod/lib/python3.11/site-packages/django/core/handlers/exception.py", line 55, in inner
    response = get_response(request)
               ^^^^^^^^^^^^^^^^^^^^^
  File "/home/zaffarelli/.virtualenvs/owod/lib/python3.11/site-packages/django/core/handlers/base.py", line 197, in _get_response
    response = wrapped_callback(request, *callback_args, **callback_kwargs)
               ^^^^^^^^^^^^^^^^^^^^^^^^^^^^^^^^^^^^^^^^^^^^^^^^^^^^^^^^^^^^
  File "/home/zaffarelli/.virtualenvs/owod/lib/python3.11/site-packages/django/contrib/admin/options.py", line 688, in wrapper
    return self.admin_site.admin_view(view)(*args, **kwargs)
           ^^^^^^^^^^^^^^^^^^^^^^^^^^^^^^^^^^^^^^^^^^^^^^^^^
  File "/home/zaffarelli/.virtualenvs/owod/lib/python3.11/site-packages/django/utils/decorators.py", line 134, in _wrapper_view
    response = view_func(request, *args, **kwargs)
               ^^^^^^^^^^^^^^^^^^^^^^^^^^^^^^^^^^^
  File "/home/zaffarelli/.virtualenvs/owod/lib/python3.11/site-packages/django/views/decorators/cache.py", line 62, in _wrapper_view_func
    response = view_func(request, *args, **kwargs)
               ^^^^^^^^^^^^^^^^^^^^^^^^^^^^^^^^^^^
  File "/home/zaffarelli/.virtualenvs/owod/lib/python3.11/site-packages/django/contrib/admin/sites.py", line 242, in inner
    return view(request, *args, **kwargs)
           ^^^^^^^^^^^^^^^^^^^^^^^^^^^^^^
  File "/home/zaffarelli/.virtualenvs/owod/lib/python3.11/site-packages/django/contrib/admin/options.py", line 1889, in change_view
    return self.changeform_view(request, object_id, form_url, extra_context)
           ^^^^^^^^^^^^^^^^^^^^^^^^^^^^^^^^^^^^^^^^^^^^^^^^^^^^^^^^^^^^^^^^^
  File "/home/zaffarelli/.virtualenvs/owod/lib/python3.11/site-packages/django/utils/decorators.py", line 46, in _wrapper
    return bound_method(*args, **kwargs)
           ^^^^^^^^^^^^^^^^^^^^^^^^^^^^^
  File "/home/zaffarelli/.virtualenvs/owod/lib/python3.11/site-packages/django/utils/decorators.py", line 134, in _wrapper_view
    response = view_func(request, *args, **kwargs)
               ^^^^^^^^^^^^^^^^^^^^^^^^^^^^^^^^^^^
  File "/home/zaffarelli/.virtualenvs/owod/lib/python3.11/site-packages/django/contrib/admin/options.py", line 1747, in changeform_view
    return self._changeform_view(request, object_id, form_url, extra_context)
           ^^^^^^^^^^^^^^^^^^^^^^^^^^^^^^^^^^^^^^^^^^^^^^^^^^^^^^^^^^^^^^^^^^
  File "/home/zaffarelli/.virtualenvs/owod/lib/python3.11/site-packages/django/contrib/admin/options.py", line 1798, in _changeform_view
    self.save_model(request, new_object, form, not add)
  File "/home/zaffarelli/.virtualenvs/owod/lib/python3.11/site-packages/django/contrib/admin/options.py", line 1227, in save_model
    obj.save()
  File "/home/zaffarelli/.virtualenvs/owod/lib/python3.11/site-packages/django/db/models/base.py", line 814, in save
    self.save_base(
  File "/home/zaffarelli/.virtualenvs/owod/lib/python3.11/site-packages/django/db/models/base.py", line 861, in save_base
    pre_save.send(
  File "/home/zaffarelli/.virtualenvs/owod/lib/python3.11/site-packages/django/dispatch/dispatcher.py", line 176, in send
    return [
           ^
  File "/home/zaffarelli/.virtualenvs/owod/lib/python3.11/site-packages/django/dispatch/dispatcher.py", line 177, in <listcomp>
    (receiver, receiver(signal=self, sender=sender, **named))
               ^^^^^^^^^^^^^^^^^^^^^^^^^^^^^^^^^^^^^^^^^^^^^
  File "/home/zaffarelli/Perso/github/wawwod/collector/signals/creatures.py", line 18, in update_creature
    instance.fix()
  File "/home/zaffarelli/Perso/github/wawwod/collector/models/creatures.py", line 691, in fix
    self.fix_garou()
  File "/home/zaffarelli/Perso/github/wawwod/collector/models/creatures.py", line 656, in fix_garou
    self.expectedfreebies = self.freebies_per_mortal_age + expected_freebies_by_rank[self.rank - 1]
                                                                                     ~~~~~~~~~~^~~
TypeError: unsupported operand type(s) for -: 'str' and 'int'
[12/06 15:49:43] "POST /admin/collector/creature/775/change/?_changelist_filters=adventure__name__exact%3DThe%2BWeeping%2BTree HTTP/1.1" 500 193490
[12/06 15:52:03] Not Found: /favicon.ico
[12/06 15:53:43] "GET /static/collector/tribes/s.webp HTTP/1.1" 404 1825
[12/06 15:54:38] "GET /static/collector/tribes/silver_fangss.webp HTTP/1.1" 404 1861
[12/06 15:54:44] "GET /static/collector/tribes/black_furiess.webp HTTP/1.1" 404 1861
[12/06 15:54:51] "GET /static/collector/tribes/silver_fangss.webp HTTP/1.1" 404 1861
[12/06 15:55:06] "GET /static/collector/tribes/silver_fangss.webp HTTP/1.1" 404 1861
[12/06 15:55:10] "GET /static/collector/tribes/black_furiess.webp HTTP/1.1" 404 1861
[12/06 15:56:07] "GET /static/storytelling/fonts/Lato-Regular.ttf HTTP/1.1" 404 1861
[12/06 15:56:36] Not Found: /ajax/display/crossover_sheet/Get of Fenris/
[12/06 15:56:36] "GET /ajax/display/crossover_sheet/Get%20of%20Fenris/ HTTP/1.1" 404 8787
[12/06 15:56:48] Not Found: /ajax/display/crossover_sheet/Get of Fenris/
[12/06 15:56:48] "GET /ajax/display/crossover_sheet/Get%20of%20Fenris/ HTTP/1.1" 404 8787
[12/06 15:56:54] Not Found: /ajax/display/crossover_sheet/Get of Fenris/
[12/06 15:56:54] "GET /ajax/display/crossover_sheet/Get%20of%20Fenris/ HTTP/1.1" 404 8787
[12/06 15:56:59] Not Found: /ajax/display/crossover_sheet/Get of Fenris/
[12/06 15:56:59] "GET /ajax/display/crossover_sheet/Get%20of%20Fenris/ HTTP/1.1" 404 8787
[12/06 17:23:39] "GET /static/storytelling/fonts/Lato-Regular.ttf HTTP/1.1" 404 1861
[12/06 17:24:19] "GET /static/storytelling/fonts/Lato-Regular.ttf HTTP/1.1" 404 1861
[12/06 17:26:08] "GET /static/storytelling/fonts/Lato-Regular.ttf HTTP/1.1" 404 1861
[12/06 17:28:03] "GET /static/storytelling/fonts/Lato-Regular.ttf HTTP/1.1" 404 1861
[12/06 17:29:37] Internal Server Error: /ajax/view/creature/_elisabeth_koffmann/
Traceback (most recent call last):
  File "/home/zaffarelli/.virtualenvs/owod/lib/python3.11/site-packages/django/template/base.py", line 505, in parse
    compile_func = self.tags[command]
                   ~~~~~~~~~^^^^^^^^^
KeyError: 'else'

During handling of the above exception, another exception occurred:

Traceback (most recent call last):
  File "/home/zaffarelli/.virtualenvs/owod/lib/python3.11/site-packages/django/core/handlers/exception.py", line 55, in inner
    response = get_response(request)
               ^^^^^^^^^^^^^^^^^^^^^
  File "/home/zaffarelli/.virtualenvs/owod/lib/python3.11/site-packages/django/core/handlers/base.py", line 220, in _get_response
    response = response.render()
               ^^^^^^^^^^^^^^^^^
  File "/home/zaffarelli/.virtualenvs/owod/lib/python3.11/site-packages/django/template/response.py", line 114, in render
    self.content = self.rendered_content
                   ^^^^^^^^^^^^^^^^^^^^^
  File "/home/zaffarelli/.virtualenvs/owod/lib/python3.11/site-packages/django/template/response.py", line 92, in rendered_content
    return template.render(context, self._request)
           ^^^^^^^^^^^^^^^^^^^^^^^^^^^^^^^^^^^^^^^
  File "/home/zaffarelli/.virtualenvs/owod/lib/python3.11/site-packages/django/template/backends/django.py", line 61, in render
    return self.template.render(context)
           ^^^^^^^^^^^^^^^^^^^^^^^^^^^^^
  File "/home/zaffarelli/.virtualenvs/owod/lib/python3.11/site-packages/django/template/base.py", line 175, in render
    return self._render(context)
           ^^^^^^^^^^^^^^^^^^^^^
  File "/home/zaffarelli/.virtualenvs/owod/lib/python3.11/site-packages/django/template/base.py", line 167, in _render
    return self.nodelist.render(context)
           ^^^^^^^^^^^^^^^^^^^^^^^^^^^^^
  File "/home/zaffarelli/.virtualenvs/owod/lib/python3.11/site-packages/django/template/base.py", line 1005, in render
    return SafeString("".join([node.render_annotated(context) for node in self]))
                              ^^^^^^^^^^^^^^^^^^^^^^^^^^^^^^^^^^^^^^^^^^^^^^^^^
  File "/home/zaffarelli/.virtualenvs/owod/lib/python3.11/site-packages/django/template/base.py", line 1005, in <listcomp>
    return SafeString("".join([node.render_annotated(context) for node in self]))
                               ^^^^^^^^^^^^^^^^^^^^^^^^^^^^^^
  File "/home/zaffarelli/.virtualenvs/owod/lib/python3.11/site-packages/django/template/base.py", line 966, in render_annotated
    return self.render(context)
           ^^^^^^^^^^^^^^^^^^^^
  File "/home/zaffarelli/.virtualenvs/owod/lib/python3.11/site-packages/django/template/loader_tags.py", line 54, in render
    result = self.nodelist.render(context)
             ^^^^^^^^^^^^^^^^^^^^^^^^^^^^^
  File "/home/zaffarelli/.virtualenvs/owod/lib/python3.11/site-packages/django/template/base.py", line 1005, in render
    return SafeString("".join([node.render_annotated(context) for node in self]))
                              ^^^^^^^^^^^^^^^^^^^^^^^^^^^^^^^^^^^^^^^^^^^^^^^^^
  File "/home/zaffarelli/.virtualenvs/owod/lib/python3.11/site-packages/django/template/base.py", line 1005, in <listcomp>
    return SafeString("".join([node.render_annotated(context) for node in self]))
                               ^^^^^^^^^^^^^^^^^^^^^^^^^^^^^^
  File "/home/zaffarelli/.virtualenvs/owod/lib/python3.11/site-packages/django/template/base.py", line 966, in render_annotated
    return self.render(context)
           ^^^^^^^^^^^^^^^^^^^^
  File "/home/zaffarelli/.virtualenvs/owod/lib/python3.11/site-packages/django/template/defaulttags.py", line 321, in render
    return nodelist.render(context)
           ^^^^^^^^^^^^^^^^^^^^^^^^
  File "/home/zaffarelli/.virtualenvs/owod/lib/python3.11/site-packages/django/template/base.py", line 1005, in render
    return SafeString("".join([node.render_annotated(context) for node in self]))
                              ^^^^^^^^^^^^^^^^^^^^^^^^^^^^^^^^^^^^^^^^^^^^^^^^^
  File "/home/zaffarelli/.virtualenvs/owod/lib/python3.11/site-packages/django/template/base.py", line 1005, in <listcomp>
    return SafeString("".join([node.render_annotated(context) for node in self]))
                               ^^^^^^^^^^^^^^^^^^^^^^^^^^^^^^
  File "/home/zaffarelli/.virtualenvs/owod/lib/python3.11/site-packages/django/template/base.py", line 966, in render_annotated
    return self.render(context)
           ^^^^^^^^^^^^^^^^^^^^
  File "/home/zaffarelli/.virtualenvs/owod/lib/python3.11/site-packages/django/template/loader_tags.py", line 208, in render
    return template.render(context)
           ^^^^^^^^^^^^^^^^^^^^^^^^
  File "/home/zaffarelli/.virtualenvs/owod/lib/python3.11/site-packages/django/template/base.py", line 177, in render
    return self._render(context)
           ^^^^^^^^^^^^^^^^^^^^^
  File "/home/zaffarelli/.virtualenvs/owod/lib/python3.11/site-packages/django/template/base.py", line 167, in _render
    return self.nodelist.render(context)
           ^^^^^^^^^^^^^^^^^^^^^^^^^^^^^
  File "/home/zaffarelli/.virtualenvs/owod/lib/python3.11/site-packages/django/template/base.py", line 1005, in render
    return SafeString("".join([node.render_annotated(context) for node in self]))
                              ^^^^^^^^^^^^^^^^^^^^^^^^^^^^^^^^^^^^^^^^^^^^^^^^^
  File "/home/zaffarelli/.virtualenvs/owod/lib/python3.11/site-packages/django/template/base.py", line 1005, in <listcomp>
    return SafeString("".join([node.render_annotated(context) for node in self]))
                               ^^^^^^^^^^^^^^^^^^^^^^^^^^^^^^
  File "/home/zaffarelli/.virtualenvs/owod/lib/python3.11/site-packages/django/template/base.py", line 966, in render_annotated
    return self.render(context)
           ^^^^^^^^^^^^^^^^^^^^
  File "/home/zaffarelli/.virtualenvs/owod/lib/python3.11/site-packages/django/template/loader_tags.py", line 197, in render
    template = context.template.engine.select_template(template_name)
               ^^^^^^^^^^^^^^^^^^^^^^^^^^^^^^^^^^^^^^^^^^^^^^^^^^^^^^
  File "/home/zaffarelli/.virtualenvs/owod/lib/python3.11/site-packages/django/template/engine.py", line 206, in select_template
    return self.get_template(template_name)
           ^^^^^^^^^^^^^^^^^^^^^^^^^^^^^^^^
  File "/home/zaffarelli/.virtualenvs/owod/lib/python3.11/site-packages/django/template/engine.py", line 175, in get_template
    template, origin = self.find_template(template_name)
                       ^^^^^^^^^^^^^^^^^^^^^^^^^^^^^^^^^
  File "/home/zaffarelli/.virtualenvs/owod/lib/python3.11/site-packages/django/template/engine.py", line 157, in find_template
    template = loader.get_template(name, skip=skip)
               ^^^^^^^^^^^^^^^^^^^^^^^^^^^^^^^^^^^^
  File "/home/zaffarelli/.virtualenvs/owod/lib/python3.11/site-packages/django/template/loaders/cached.py", line 57, in get_template
    template = super().get_template(template_name, skip)
               ^^^^^^^^^^^^^^^^^^^^^^^^^^^^^^^^^^^^^^^^^
  File "/home/zaffarelli/.virtualenvs/owod/lib/python3.11/site-packages/django/template/loaders/base.py", line 28, in get_template
    return Template(
           ^^^^^^^^^
  File "/home/zaffarelli/.virtualenvs/owod/lib/python3.11/site-packages/django/template/base.py", line 154, in __init__
    self.nodelist = self.compile_nodelist()
                    ^^^^^^^^^^^^^^^^^^^^^^^
  File "/home/zaffarelli/.virtualenvs/owod/lib/python3.11/site-packages/django/template/base.py", line 200, in compile_nodelist
    return parser.parse()
           ^^^^^^^^^^^^^^
  File "/home/zaffarelli/.virtualenvs/owod/lib/python3.11/site-packages/django/template/base.py", line 513, in parse
    raise self.error(token, e)
  File "/home/zaffarelli/.virtualenvs/owod/lib/python3.11/site-packages/django/template/base.py", line 511, in parse
    compiled_result = compile_func(self, token)
                      ^^^^^^^^^^^^^^^^^^^^^^^^^
  File "/home/zaffarelli/.virtualenvs/owod/lib/python3.11/site-packages/django/template/defaulttags.py", line 967, in do_if
    nodelist = parser.parse(("endif",))
               ^^^^^^^^^^^^^^^^^^^^^^^^
  File "/home/zaffarelli/.virtualenvs/owod/lib/python3.11/site-packages/django/template/base.py", line 507, in parse
    self.invalid_block_tag(token, command, parse_until)
  File "/home/zaffarelli/.virtualenvs/owod/lib/python3.11/site-packages/django/template/base.py", line 558, in invalid_block_tag
    raise self.error(
django.template.exceptions.TemplateSyntaxError: Invalid block tag on line 68: 'else', expected 'endif'. Did you forget to register or load this tag?
[12/06 17:29:37] "GET /ajax/view/creature/_elisabeth_koffmann/ HTTP/1.1" 500 309771
[12/06 17:30:20] "GET /static/storytelling/fonts/Lato-Regular.ttf HTTP/1.1" 404 1861
[12/06 17:30:29] "GET /static/storytelling/fonts/Lato-Regular.ttf HTTP/1.1" 404 1861
[12/06 17:31:25] "GET /static/storytelling/fonts/Lato-Regular.ttf HTTP/1.1" 404 1861
[12/06 17:35:42] Internal Server Error: /ajax/display/gaia_wheel/
Traceback (most recent call last):
  File "/home/zaffarelli/.virtualenvs/owod/lib/python3.11/site-packages/django/core/handlers/exception.py", line 55, in inner
    response = get_response(request)
               ^^^^^^^^^^^^^^^^^^^^^
  File "/home/zaffarelli/.virtualenvs/owod/lib/python3.11/site-packages/django/core/handlers/base.py", line 197, in _get_response
    response = wrapped_callback(request, *callback_args, **callback_kwargs)
               ^^^^^^^^^^^^^^^^^^^^^^^^^^^^^^^^^^^^^^^^^^^^^^^^^^^^^^^^^^^^
  File "/home/zaffarelli/Perso/github/wawwod/collector/views/base.py", line 287, in display_gaia_wheel
    gaia_wheel_context = {'data': build_gaia_wheel()}
                                  ^^^^^^^^^^^^^^^^^^
  File "/home/zaffarelli/Perso/github/wawwod/collector/utils/data_collection.py", line 311, in build_gaia_wheel
    creature.save()
  File "/home/zaffarelli/.virtualenvs/owod/lib/python3.11/site-packages/django/db/models/base.py", line 814, in save
    self.save_base(
  File "/home/zaffarelli/.virtualenvs/owod/lib/python3.11/site-packages/django/db/models/base.py", line 861, in save_base
    pre_save.send(
  File "/home/zaffarelli/.virtualenvs/owod/lib/python3.11/site-packages/django/dispatch/dispatcher.py", line 176, in send
    return [
           ^
  File "/home/zaffarelli/.virtualenvs/owod/lib/python3.11/site-packages/django/dispatch/dispatcher.py", line 177, in <listcomp>
    (receiver, receiver(signal=self, sender=sender, **named))
               ^^^^^^^^^^^^^^^^^^^^^^^^^^^^^^^^^^^^^^^^^^^^^
  File "/home/zaffarelli/Perso/github/wawwod/collector/signals/creatures.py", line 18, in update_creature
    instance.fix()
  File "/home/zaffarelli/Perso/github/wawwod/collector/models/creatures.py", line 697, in fix
    self.fix_ghoul()
  File "/home/zaffarelli/Perso/github/wawwod/collector/models/creatures.py", line 490, in fix_ghoul
    domitor = Creature.objects.get(rid=self.sire)
              ^^^^^^^^^^^^^^^^^^^^^^^^^^^^^^^^^^^
  File "/home/zaffarelli/.virtualenvs/owod/lib/python3.11/site-packages/django/db/models/manager.py", line 87, in manager_method
    return getattr(self.get_queryset(), name)(*args, **kwargs)
           ^^^^^^^^^^^^^^^^^^^^^^^^^^^^^^^^^^^^^^^^^^^^^^^^^^^
  File "/home/zaffarelli/.virtualenvs/owod/lib/python3.11/site-packages/django/db/models/query.py", line 637, in get
    raise self.model.DoesNotExist(
collector.models.creatures.Creature.DoesNotExist: Creature matching query does not exist.
[12/06 17:35:42] "GET /ajax/display/gaia_wheel/ HTTP/1.1" 500 122475
[12/06 17:36:12] Internal Server Error: /ajax/display/gaia_wheel/
Traceback (most recent call last):
  File "/home/zaffarelli/.virtualenvs/owod/lib/python3.11/site-packages/django/core/handlers/exception.py", line 55, in inner
    response = get_response(request)
               ^^^^^^^^^^^^^^^^^^^^^
  File "/home/zaffarelli/.virtualenvs/owod/lib/python3.11/site-packages/django/core/handlers/base.py", line 197, in _get_response
    response = wrapped_callback(request, *callback_args, **callback_kwargs)
               ^^^^^^^^^^^^^^^^^^^^^^^^^^^^^^^^^^^^^^^^^^^^^^^^^^^^^^^^^^^^
  File "/home/zaffarelli/Perso/github/wawwod/collector/views/base.py", line 287, in display_gaia_wheel
    gaia_wheel_context = {'data': build_gaia_wheel()}
                                  ^^^^^^^^^^^^^^^^^^
  File "/home/zaffarelli/Perso/github/wawwod/collector/utils/data_collection.py", line 311, in build_gaia_wheel
    creature.save()
  File "/home/zaffarelli/.virtualenvs/owod/lib/python3.11/site-packages/django/db/models/base.py", line 814, in save
    self.save_base(
  File "/home/zaffarelli/.virtualenvs/owod/lib/python3.11/site-packages/django/db/models/base.py", line 861, in save_base
    pre_save.send(
  File "/home/zaffarelli/.virtualenvs/owod/lib/python3.11/site-packages/django/dispatch/dispatcher.py", line 176, in send
    return [
           ^
  File "/home/zaffarelli/.virtualenvs/owod/lib/python3.11/site-packages/django/dispatch/dispatcher.py", line 177, in <listcomp>
    (receiver, receiver(signal=self, sender=sender, **named))
               ^^^^^^^^^^^^^^^^^^^^^^^^^^^^^^^^^^^^^^^^^^^^^
  File "/home/zaffarelli/Perso/github/wawwod/collector/signals/creatures.py", line 18, in update_creature
    instance.fix()
  File "/home/zaffarelli/Perso/github/wawwod/collector/models/creatures.py", line 697, in fix
    self.fix_ghoul()
  File "/home/zaffarelli/Perso/github/wawwod/collector/models/creatures.py", line 490, in fix_ghoul
    domitor = Creature.objects.get(rid=self.sire)
              ^^^^^^^^^^^^^^^^^^^^^^^^^^^^^^^^^^^
  File "/home/zaffarelli/.virtualenvs/owod/lib/python3.11/site-packages/django/db/models/manager.py", line 87, in manager_method
    return getattr(self.get_queryset(), name)(*args, **kwargs)
           ^^^^^^^^^^^^^^^^^^^^^^^^^^^^^^^^^^^^^^^^^^^^^^^^^^^
  File "/home/zaffarelli/.virtualenvs/owod/lib/python3.11/site-packages/django/db/models/query.py", line 637, in get
    raise self.model.DoesNotExist(
collector.models.creatures.Creature.DoesNotExist: Creature matching query does not exist.
[12/06 17:36:12] "GET /ajax/display/gaia_wheel/ HTTP/1.1" 500 122491
[12/06 21:57:26] Internal Server Error: /ajax/display/gaia_wheel/
Traceback (most recent call last):
  File "/home/zaffarelli/.virtualenvs/owod/lib/python3.11/site-packages/django/core/handlers/exception.py", line 55, in inner
    response = get_response(request)
               ^^^^^^^^^^^^^^^^^^^^^
  File "/home/zaffarelli/.virtualenvs/owod/lib/python3.11/site-packages/django/core/handlers/base.py", line 197, in _get_response
    response = wrapped_callback(request, *callback_args, **callback_kwargs)
               ^^^^^^^^^^^^^^^^^^^^^^^^^^^^^^^^^^^^^^^^^^^^^^^^^^^^^^^^^^^^
  File "/home/zaffarelli/Perso/github/wawwod/collector/views/base.py", line 287, in display_gaia_wheel
    gaia_wheel_context = {'data': build_gaia_wheel()}
                                  ^^^^^^^^^^^^^^^^^^
  File "/home/zaffarelli/Perso/github/wawwod/collector/utils/data_collection.py", line 311, in build_gaia_wheel
    creature.save()
  File "/home/zaffarelli/.virtualenvs/owod/lib/python3.11/site-packages/django/db/models/base.py", line 814, in save
    self.save_base(
  File "/home/zaffarelli/.virtualenvs/owod/lib/python3.11/site-packages/django/db/models/base.py", line 861, in save_base
    pre_save.send(
  File "/home/zaffarelli/.virtualenvs/owod/lib/python3.11/site-packages/django/dispatch/dispatcher.py", line 176, in send
    return [
           ^
  File "/home/zaffarelli/.virtualenvs/owod/lib/python3.11/site-packages/django/dispatch/dispatcher.py", line 177, in <listcomp>
    (receiver, receiver(signal=self, sender=sender, **named))
               ^^^^^^^^^^^^^^^^^^^^^^^^^^^^^^^^^^^^^^^^^^^^^
  File "/home/zaffarelli/Perso/github/wawwod/collector/signals/creatures.py", line 18, in update_creature
    instance.fix()
  File "/home/zaffarelli/Perso/github/wawwod/collector/models/creatures.py", line 697, in fix
    self.fix_ghoul()
  File "/home/zaffarelli/Perso/github/wawwod/collector/models/creatures.py", line 490, in fix_ghoul
    domitor = Creature.objects.get(rid=self.sire)
              ^^^^^^^^^^^^^^^^^^^^^^^^^^^^^^^^^^^
  File "/home/zaffarelli/.virtualenvs/owod/lib/python3.11/site-packages/django/db/models/manager.py", line 87, in manager_method
    return getattr(self.get_queryset(), name)(*args, **kwargs)
           ^^^^^^^^^^^^^^^^^^^^^^^^^^^^^^^^^^^^^^^^^^^^^^^^^^^
  File "/home/zaffarelli/.virtualenvs/owod/lib/python3.11/site-packages/django/db/models/query.py", line 637, in get
    raise self.model.DoesNotExist(
collector.models.creatures.Creature.DoesNotExist: Creature matching query does not exist.
[12/06 21:57:26] "GET /ajax/display/gaia_wheel/ HTTP/1.1" 500 122491
[12/06 21:59:18] Internal Server Error: /ajax/display/gaia_wheel/
Traceback (most recent call last):
  File "/home/zaffarelli/.virtualenvs/owod/lib/python3.11/site-packages/django/core/handlers/exception.py", line 55, in inner
    response = get_response(request)
               ^^^^^^^^^^^^^^^^^^^^^
  File "/home/zaffarelli/.virtualenvs/owod/lib/python3.11/site-packages/django/core/handlers/base.py", line 197, in _get_response
    response = wrapped_callback(request, *callback_args, **callback_kwargs)
               ^^^^^^^^^^^^^^^^^^^^^^^^^^^^^^^^^^^^^^^^^^^^^^^^^^^^^^^^^^^^
  File "/home/zaffarelli/Perso/github/wawwod/collector/views/base.py", line 287, in display_gaia_wheel
    gaia_wheel_context = {'data': build_gaia_wheel()}
                                  ^^^^^^^^^^^^^^^^^^
  File "/home/zaffarelli/Perso/github/wawwod/collector/utils/data_collection.py", line 311, in build_gaia_wheel
    creature.save()
  File "/home/zaffarelli/.virtualenvs/owod/lib/python3.11/site-packages/django/db/models/base.py", line 814, in save
    self.save_base(
  File "/home/zaffarelli/.virtualenvs/owod/lib/python3.11/site-packages/django/db/models/base.py", line 861, in save_base
    pre_save.send(
  File "/home/zaffarelli/.virtualenvs/owod/lib/python3.11/site-packages/django/dispatch/dispatcher.py", line 176, in send
    return [
           ^
  File "/home/zaffarelli/.virtualenvs/owod/lib/python3.11/site-packages/django/dispatch/dispatcher.py", line 177, in <listcomp>
    (receiver, receiver(signal=self, sender=sender, **named))
               ^^^^^^^^^^^^^^^^^^^^^^^^^^^^^^^^^^^^^^^^^^^^^
  File "/home/zaffarelli/Perso/github/wawwod/collector/signals/creatures.py", line 18, in update_creature
    instance.fix()
  File "/home/zaffarelli/Perso/github/wawwod/collector/models/creatures.py", line 697, in fix
    self.fix_ghoul()
  File "/home/zaffarelli/Perso/github/wawwod/collector/models/creatures.py", line 490, in fix_ghoul
    domitor = Creature.objects.get(rid=self.sire)
              ^^^^^^^^^^^^^^^^^^^^^^^^^^^^^^^^^^^
  File "/home/zaffarelli/.virtualenvs/owod/lib/python3.11/site-packages/django/db/models/manager.py", line 87, in manager_method
    return getattr(self.get_queryset(), name)(*args, **kwargs)
           ^^^^^^^^^^^^^^^^^^^^^^^^^^^^^^^^^^^^^^^^^^^^^^^^^^^
  File "/home/zaffarelli/.virtualenvs/owod/lib/python3.11/site-packages/django/db/models/query.py", line 637, in get
    raise self.model.DoesNotExist(
collector.models.creatures.Creature.DoesNotExist: Creature matching query does not exist.
[12/06 21:59:18] "GET /ajax/display/gaia_wheel/ HTTP/1.1" 500 122491
[12/06 22:00:09] Internal Server Error: /ajax/display/gaia_wheel/
Traceback (most recent call last):
  File "/home/zaffarelli/.virtualenvs/owod/lib/python3.11/site-packages/django/core/handlers/exception.py", line 55, in inner
    response = get_response(request)
               ^^^^^^^^^^^^^^^^^^^^^
  File "/home/zaffarelli/.virtualenvs/owod/lib/python3.11/site-packages/django/core/handlers/base.py", line 197, in _get_response
    response = wrapped_callback(request, *callback_args, **callback_kwargs)
               ^^^^^^^^^^^^^^^^^^^^^^^^^^^^^^^^^^^^^^^^^^^^^^^^^^^^^^^^^^^^
  File "/home/zaffarelli/Perso/github/wawwod/collector/views/base.py", line 287, in display_gaia_wheel
    gaia_wheel_context = {'data': build_gaia_wheel()}
                                  ^^^^^^^^^^^^^^^^^^
  File "/home/zaffarelli/Perso/github/wawwod/collector/utils/data_collection.py", line 311, in build_gaia_wheel
    creature.save()
  File "/home/zaffarelli/.virtualenvs/owod/lib/python3.11/site-packages/django/db/models/base.py", line 814, in save
    self.save_base(
  File "/home/zaffarelli/.virtualenvs/owod/lib/python3.11/site-packages/django/db/models/base.py", line 861, in save_base
    pre_save.send(
  File "/home/zaffarelli/.virtualenvs/owod/lib/python3.11/site-packages/django/dispatch/dispatcher.py", line 176, in send
    return [
           ^
  File "/home/zaffarelli/.virtualenvs/owod/lib/python3.11/site-packages/django/dispatch/dispatcher.py", line 177, in <listcomp>
    (receiver, receiver(signal=self, sender=sender, **named))
               ^^^^^^^^^^^^^^^^^^^^^^^^^^^^^^^^^^^^^^^^^^^^^
  File "/home/zaffarelli/Perso/github/wawwod/collector/signals/creatures.py", line 18, in update_creature
    instance.fix()
  File "/home/zaffarelli/Perso/github/wawwod/collector/models/creatures.py", line 698, in fix
    self.fix_ghoul()
  File "/home/zaffarelli/Perso/github/wawwod/collector/models/creatures.py", line 491, in fix_ghoul
    domitor = Creature.objects.get(rid=self.sire)
              ^^^^^^^^^^^^^^^^^^^^^^^^^^^^^^^^^^^
  File "/home/zaffarelli/.virtualenvs/owod/lib/python3.11/site-packages/django/db/models/manager.py", line 87, in manager_method
    return getattr(self.get_queryset(), name)(*args, **kwargs)
           ^^^^^^^^^^^^^^^^^^^^^^^^^^^^^^^^^^^^^^^^^^^^^^^^^^^
  File "/home/zaffarelli/.virtualenvs/owod/lib/python3.11/site-packages/django/db/models/query.py", line 637, in get
    raise self.model.DoesNotExist(
collector.models.creatures.Creature.DoesNotExist: Creature matching query does not exist.
[12/06 22:00:09] "GET /ajax/display/gaia_wheel/ HTTP/1.1" 500 122495
[12/06 22:00:33] Not Found: /favicon.ico
[12/06 22:00:38] Not Found: /favicon.ico
[12/06 22:01:44] Not Found: /favicon.ico
[12/06 22:02:21] Not Found: /favicon.ico
[12/06 22:02:50] Not Found: /favicon.ico
[12/06 22:03:15] Internal Server Error: /ajax/display/gaia_wheel/
Traceback (most recent call last):
  File "/home/zaffarelli/.virtualenvs/owod/lib/python3.11/site-packages/django/core/handlers/exception.py", line 55, in inner
    response = get_response(request)
               ^^^^^^^^^^^^^^^^^^^^^
  File "/home/zaffarelli/.virtualenvs/owod/lib/python3.11/site-packages/django/core/handlers/base.py", line 197, in _get_response
    response = wrapped_callback(request, *callback_args, **callback_kwargs)
               ^^^^^^^^^^^^^^^^^^^^^^^^^^^^^^^^^^^^^^^^^^^^^^^^^^^^^^^^^^^^
  File "/home/zaffarelli/Perso/github/wawwod/collector/views/base.py", line 287, in display_gaia_wheel
    gaia_wheel_context = {'data': build_gaia_wheel()}
                                  ^^^^^^^^^^^^^^^^^^
  File "/home/zaffarelli/Perso/github/wawwod/collector/utils/data_collection.py", line 311, in build_gaia_wheel
    creature.save()
  File "/home/zaffarelli/.virtualenvs/owod/lib/python3.11/site-packages/django/db/models/base.py", line 814, in save
    self.save_base(
  File "/home/zaffarelli/.virtualenvs/owod/lib/python3.11/site-packages/django/db/models/base.py", line 861, in save_base
    pre_save.send(
  File "/home/zaffarelli/.virtualenvs/owod/lib/python3.11/site-packages/django/dispatch/dispatcher.py", line 176, in send
    return [
           ^
  File "/home/zaffarelli/.virtualenvs/owod/lib/python3.11/site-packages/django/dispatch/dispatcher.py", line 177, in <listcomp>
    (receiver, receiver(signal=self, sender=sender, **named))
               ^^^^^^^^^^^^^^^^^^^^^^^^^^^^^^^^^^^^^^^^^^^^^
  File "/home/zaffarelli/Perso/github/wawwod/collector/signals/creatures.py", line 18, in update_creature
    instance.fix()
  File "/home/zaffarelli/Perso/github/wawwod/collector/models/creatures.py", line 698, in fix
    self.fix_ghoul()
  File "/home/zaffarelli/Perso/github/wawwod/collector/models/creatures.py", line 491, in fix_ghoul
    domitor = Creature.objects.get(rid=self.sire)
              ^^^^^^^^^^^^^^^^^^^^^^^^^^^^^^^^^^^
  File "/home/zaffarelli/.virtualenvs/owod/lib/python3.11/site-packages/django/db/models/manager.py", line 87, in manager_method
    return getattr(self.get_queryset(), name)(*args, **kwargs)
           ^^^^^^^^^^^^^^^^^^^^^^^^^^^^^^^^^^^^^^^^^^^^^^^^^^^
  File "/home/zaffarelli/.virtualenvs/owod/lib/python3.11/site-packages/django/db/models/query.py", line 637, in get
    raise self.model.DoesNotExist(
collector.models.creatures.Creature.DoesNotExist: Creature matching query does not exist.
[12/06 22:03:15] "GET /ajax/display/gaia_wheel/ HTTP/1.1" 500 122465
[12/06 22:03:44] Not Found: /favicon.ico
[12/06 22:03:53] Not Found: /favicon.ico
[12/06 22:04:11] Internal Server Error: /ajax/display/gaia_wheel/
Traceback (most recent call last):
  File "/home/zaffarelli/.virtualenvs/owod/lib/python3.11/site-packages/django/core/handlers/exception.py", line 55, in inner
    response = get_response(request)
               ^^^^^^^^^^^^^^^^^^^^^
  File "/home/zaffarelli/.virtualenvs/owod/lib/python3.11/site-packages/django/core/handlers/base.py", line 197, in _get_response
    response = wrapped_callback(request, *callback_args, **callback_kwargs)
               ^^^^^^^^^^^^^^^^^^^^^^^^^^^^^^^^^^^^^^^^^^^^^^^^^^^^^^^^^^^^
  File "/home/zaffarelli/Perso/github/wawwod/collector/views/base.py", line 287, in display_gaia_wheel
    gaia_wheel_context = {'data': build_gaia_wheel()}
                                  ^^^^^^^^^^^^^^^^^^
  File "/home/zaffarelli/Perso/github/wawwod/collector/utils/data_collection.py", line 311, in build_gaia_wheel
    creature.save()
  File "/home/zaffarelli/.virtualenvs/owod/lib/python3.11/site-packages/django/db/models/base.py", line 814, in save
    self.save_base(
  File "/home/zaffarelli/.virtualenvs/owod/lib/python3.11/site-packages/django/db/models/base.py", line 861, in save_base
    pre_save.send(
  File "/home/zaffarelli/.virtualenvs/owod/lib/python3.11/site-packages/django/dispatch/dispatcher.py", line 176, in send
    return [
           ^
  File "/home/zaffarelli/.virtualenvs/owod/lib/python3.11/site-packages/django/dispatch/dispatcher.py", line 177, in <listcomp>
    (receiver, receiver(signal=self, sender=sender, **named))
               ^^^^^^^^^^^^^^^^^^^^^^^^^^^^^^^^^^^^^^^^^^^^^
  File "/home/zaffarelli/Perso/github/wawwod/collector/signals/creatures.py", line 18, in update_creature
    instance.fix()
  File "/home/zaffarelli/Perso/github/wawwod/collector/models/creatures.py", line 698, in fix
    self.fix_ghoul()
  File "/home/zaffarelli/Perso/github/wawwod/collector/models/creatures.py", line 491, in fix_ghoul
    domitor = Creature.objects.get(rid=self.sire)
              ^^^^^^^^^^^^^^^^^^^^^^^^^^^^^^^^^^^
  File "/home/zaffarelli/.virtualenvs/owod/lib/python3.11/site-packages/django/db/models/manager.py", line 87, in manager_method
    return getattr(self.get_queryset(), name)(*args, **kwargs)
           ^^^^^^^^^^^^^^^^^^^^^^^^^^^^^^^^^^^^^^^^^^^^^^^^^^^
  File "/home/zaffarelli/.virtualenvs/owod/lib/python3.11/site-packages/django/db/models/query.py", line 637, in get
    raise self.model.DoesNotExist(
collector.models.creatures.Creature.DoesNotExist: Creature matching query does not exist.
[12/06 22:04:11] "GET /ajax/display/gaia_wheel/ HTTP/1.1" 500 122503
[12/06 22:04:27] Not Found: /favicon.ico
[12/06 22:06:46] "GET /static/storytelling/fonts/Lato-Regular.ttf HTTP/1.1" 404 1861
[12/06 22:31:46] "GET /static/collector/clans/blood_brothers.webp HTTP/1.1" 404 1861
[12/06 22:31:46] "GET /static/collector/clans/gargoyle.webp HTTP/1.1" 404 1843
[12/06 22:33:06] "GET /static/collector/clans/blood_brothers.webp HTTP/1.1" 404 1861
[12/06 22:33:06] "GET /static/collector/clans/gargoyle.webp HTTP/1.1" 404 1843
[12/06 22:33:18] "GET /static/storytelling/fonts/Lato-Regular.ttf HTTP/1.1" 404 1861
[12/06 22:34:28] "GET /static/collector/clans/blood_brothers.webp HTTP/1.1" 404 1861
[12/06 22:34:28] "GET /static/collector/clans/gargoyle.webp HTTP/1.1" 404 1843
[12/06 22:35:19] "GET /static/collector/clans/blood_brothers.webp HTTP/1.1" 404 1861
[12/06 22:35:19] "GET /static/collector/clans/gargoyle.webp HTTP/1.1" 404 1843
[12/06 22:35:34] "GET /static/collector/clans/blood_brothers.webp HTTP/1.1" 404 1861
[12/06 22:35:34] "GET /static/collector/clans/gargoyle.webp HTTP/1.1" 404 1843
[12/06 22:35:48] "GET /static/collector/clans/blood_brothers.webp HTTP/1.1" 404 1861
[12/06 22:35:48] "GET /static/collector/clans/gargoyle.webp HTTP/1.1" 404 1843
[12/06 22:37:12] "GET /static/collector/clans/gargoyle.webp HTTP/1.1" 404 1843
[12/06 22:37:12] "GET /static/collector/clans/blood_brothers.webp HTTP/1.1" 404 1861
[12/06 22:38:20] "GET /static/collector/clans/blood_brothers.webp HTTP/1.1" 404 1861
[12/06 22:38:20] "GET /static/collector/clans/gargoyle.webp HTTP/1.1" 404 1843
[12/06 22:38:26] Internal Server Error: /ajax/display/gaia_wheel/
Traceback (most recent call last):
  File "/home/zaffarelli/.virtualenvs/owod/lib/python3.11/site-packages/django/db/backends/utils.py", line 89, in _execute
    return self.cursor.execute(sql, params)
           ^^^^^^^^^^^^^^^^^^^^^^^^^^^^^^^^
  File "/home/zaffarelli/.virtualenvs/owod/lib/python3.11/site-packages/django/db/backends/mysql/base.py", line 75, in execute
    return self.cursor.execute(query, args)
           ^^^^^^^^^^^^^^^^^^^^^^^^^^^^^^^^
  File "/home/zaffarelli/.virtualenvs/owod/lib64/python3.11/site-packages/MySQLdb/cursors.py", line 206, in execute
    res = self._query(query)
          ^^^^^^^^^^^^^^^^^^
  File "/home/zaffarelli/.virtualenvs/owod/lib64/python3.11/site-packages/MySQLdb/cursors.py", line 319, in _query
    db.query(q)
  File "/home/zaffarelli/.virtualenvs/owod/lib64/python3.11/site-packages/MySQLdb/connections.py", line 254, in query
    _mysql.connection.query(self, query)
MySQLdb.DataError: (1264, "Out of range value for column 'trueage' at row 1")

The above exception was the direct cause of the following exception:

Traceback (most recent call last):
  File "/home/zaffarelli/.virtualenvs/owod/lib/python3.11/site-packages/django/core/handlers/exception.py", line 55, in inner
    response = get_response(request)
               ^^^^^^^^^^^^^^^^^^^^^
  File "/home/zaffarelli/.virtualenvs/owod/lib/python3.11/site-packages/django/core/handlers/base.py", line 197, in _get_response
    response = wrapped_callback(request, *callback_args, **callback_kwargs)
               ^^^^^^^^^^^^^^^^^^^^^^^^^^^^^^^^^^^^^^^^^^^^^^^^^^^^^^^^^^^^
  File "/home/zaffarelli/Perso/github/wawwod/collector/views/base.py", line 287, in display_gaia_wheel
    gaia_wheel_context = {'data': build_gaia_wheel()}
                                  ^^^^^^^^^^^^^^^^^^
  File "/home/zaffarelli/Perso/github/wawwod/collector/utils/data_collection.py", line 311, in build_gaia_wheel
    creature.save()
  File "/home/zaffarelli/.virtualenvs/owod/lib/python3.11/site-packages/django/db/models/base.py", line 814, in save
    self.save_base(
  File "/home/zaffarelli/.virtualenvs/owod/lib/python3.11/site-packages/django/db/models/base.py", line 877, in save_base
    updated = self._save_table(
              ^^^^^^^^^^^^^^^^^
  File "/home/zaffarelli/.virtualenvs/owod/lib/python3.11/site-packages/django/db/models/base.py", line 990, in _save_table
    updated = self._do_update(
              ^^^^^^^^^^^^^^^^
  File "/home/zaffarelli/.virtualenvs/owod/lib/python3.11/site-packages/django/db/models/base.py", line 1054, in _do_update
    return filtered._update(values) > 0
           ^^^^^^^^^^^^^^^^^^^^^^^^
  File "/home/zaffarelli/.virtualenvs/owod/lib/python3.11/site-packages/django/db/models/query.py", line 1231, in _update
    return query.get_compiler(self.db).execute_sql(CURSOR)
           ^^^^^^^^^^^^^^^^^^^^^^^^^^^^^^^^^^^^^^^^^^^^^^^
  File "/home/zaffarelli/.virtualenvs/owod/lib/python3.11/site-packages/django/db/models/sql/compiler.py", line 1982, in execute_sql
    cursor = super().execute_sql(result_type)
             ^^^^^^^^^^^^^^^^^^^^^^^^^^^^^^^^
  File "/home/zaffarelli/.virtualenvs/owod/lib/python3.11/site-packages/django/db/models/sql/compiler.py", line 1560, in execute_sql
    cursor.execute(sql, params)
  File "/home/zaffarelli/.virtualenvs/owod/lib/python3.11/site-packages/django/db/backends/utils.py", line 102, in execute
    return super().execute(sql, params)
           ^^^^^^^^^^^^^^^^^^^^^^^^^^^^
  File "/home/zaffarelli/.virtualenvs/owod/lib/python3.11/site-packages/django/db/backends/utils.py", line 67, in execute
    return self._execute_with_wrappers(
           ^^^^^^^^^^^^^^^^^^^^^^^^^^^^
  File "/home/zaffarelli/.virtualenvs/owod/lib/python3.11/site-packages/django/db/backends/utils.py", line 80, in _execute_with_wrappers
    return executor(sql, params, many, context)
           ^^^^^^^^^^^^^^^^^^^^^^^^^^^^^^^^^^^^
  File "/home/zaffarelli/.virtualenvs/owod/lib/python3.11/site-packages/django/db/backends/utils.py", line 84, in _execute
    with self.db.wrap_database_errors:
  File "/home/zaffarelli/.virtualenvs/owod/lib/python3.11/site-packages/django/db/utils.py", line 91, in __exit__
    raise dj_exc_value.with_traceback(traceback) from exc_value
  File "/home/zaffarelli/.virtualenvs/owod/lib/python3.11/site-packages/django/db/backends/utils.py", line 89, in _execute
    return self.cursor.execute(sql, params)
           ^^^^^^^^^^^^^^^^^^^^^^^^^^^^^^^^
  File "/home/zaffarelli/.virtualenvs/owod/lib/python3.11/site-packages/django/db/backends/mysql/base.py", line 75, in execute
    return self.cursor.execute(query, args)
           ^^^^^^^^^^^^^^^^^^^^^^^^^^^^^^^^
  File "/home/zaffarelli/.virtualenvs/owod/lib64/python3.11/site-packages/MySQLdb/cursors.py", line 206, in execute
    res = self._query(query)
          ^^^^^^^^^^^^^^^^^^
  File "/home/zaffarelli/.virtualenvs/owod/lib64/python3.11/site-packages/MySQLdb/cursors.py", line 319, in _query
    db.query(q)
  File "/home/zaffarelli/.virtualenvs/owod/lib64/python3.11/site-packages/MySQLdb/connections.py", line 254, in query
    _mysql.connection.query(self, query)
django.db.utils.DataError: (1264, "Out of range value for column 'trueage' at row 1")
[12/06 22:38:26] "GET /ajax/display/gaia_wheel/ HTTP/1.1" 500 311718
[12/06 22:38:38] "GET /static/collector/clans/blood_brothers.webp HTTP/1.1" 404 1861
[12/06 22:38:38] "GET /static/collector/clans/gargoyle.webp HTTP/1.1" 404 1843
[12/06 22:40:00] Internal Server Error: /ajax/display/gaia_wheel/
Traceback (most recent call last):
  File "/home/zaffarelli/.virtualenvs/owod/lib/python3.11/site-packages/django/db/backends/utils.py", line 89, in _execute
    return self.cursor.execute(sql, params)
           ^^^^^^^^^^^^^^^^^^^^^^^^^^^^^^^^
  File "/home/zaffarelli/.virtualenvs/owod/lib/python3.11/site-packages/django/db/backends/mysql/base.py", line 75, in execute
    return self.cursor.execute(query, args)
           ^^^^^^^^^^^^^^^^^^^^^^^^^^^^^^^^
  File "/home/zaffarelli/.virtualenvs/owod/lib64/python3.11/site-packages/MySQLdb/cursors.py", line 206, in execute
    res = self._query(query)
          ^^^^^^^^^^^^^^^^^^
  File "/home/zaffarelli/.virtualenvs/owod/lib64/python3.11/site-packages/MySQLdb/cursors.py", line 319, in _query
    db.query(q)
  File "/home/zaffarelli/.virtualenvs/owod/lib64/python3.11/site-packages/MySQLdb/connections.py", line 254, in query
    _mysql.connection.query(self, query)
MySQLdb.DataError: (1264, "Out of range value for column 'trueage' at row 1")

The above exception was the direct cause of the following exception:

Traceback (most recent call last):
  File "/home/zaffarelli/.virtualenvs/owod/lib/python3.11/site-packages/django/core/handlers/exception.py", line 55, in inner
    response = get_response(request)
               ^^^^^^^^^^^^^^^^^^^^^
  File "/home/zaffarelli/.virtualenvs/owod/lib/python3.11/site-packages/django/core/handlers/base.py", line 197, in _get_response
    response = wrapped_callback(request, *callback_args, **callback_kwargs)
               ^^^^^^^^^^^^^^^^^^^^^^^^^^^^^^^^^^^^^^^^^^^^^^^^^^^^^^^^^^^^
  File "/home/zaffarelli/Perso/github/wawwod/collector/views/base.py", line 287, in display_gaia_wheel
    gaia_wheel_context = {'data': build_gaia_wheel()}
                                  ^^^^^^^^^^^^^^^^^^
  File "/home/zaffarelli/Perso/github/wawwod/collector/utils/data_collection.py", line 311, in build_gaia_wheel
    creature.save()
  File "/home/zaffarelli/.virtualenvs/owod/lib/python3.11/site-packages/django/db/models/base.py", line 814, in save
    self.save_base(
  File "/home/zaffarelli/.virtualenvs/owod/lib/python3.11/site-packages/django/db/models/base.py", line 877, in save_base
    updated = self._save_table(
              ^^^^^^^^^^^^^^^^^
  File "/home/zaffarelli/.virtualenvs/owod/lib/python3.11/site-packages/django/db/models/base.py", line 990, in _save_table
    updated = self._do_update(
              ^^^^^^^^^^^^^^^^
  File "/home/zaffarelli/.virtualenvs/owod/lib/python3.11/site-packages/django/db/models/base.py", line 1054, in _do_update
    return filtered._update(values) > 0
           ^^^^^^^^^^^^^^^^^^^^^^^^
  File "/home/zaffarelli/.virtualenvs/owod/lib/python3.11/site-packages/django/db/models/query.py", line 1231, in _update
    return query.get_compiler(self.db).execute_sql(CURSOR)
           ^^^^^^^^^^^^^^^^^^^^^^^^^^^^^^^^^^^^^^^^^^^^^^^
  File "/home/zaffarelli/.virtualenvs/owod/lib/python3.11/site-packages/django/db/models/sql/compiler.py", line 1982, in execute_sql
    cursor = super().execute_sql(result_type)
             ^^^^^^^^^^^^^^^^^^^^^^^^^^^^^^^^
  File "/home/zaffarelli/.virtualenvs/owod/lib/python3.11/site-packages/django/db/models/sql/compiler.py", line 1560, in execute_sql
    cursor.execute(sql, params)
  File "/home/zaffarelli/.virtualenvs/owod/lib/python3.11/site-packages/django/db/backends/utils.py", line 102, in execute
    return super().execute(sql, params)
           ^^^^^^^^^^^^^^^^^^^^^^^^^^^^
  File "/home/zaffarelli/.virtualenvs/owod/lib/python3.11/site-packages/django/db/backends/utils.py", line 67, in execute
    return self._execute_with_wrappers(
           ^^^^^^^^^^^^^^^^^^^^^^^^^^^^
  File "/home/zaffarelli/.virtualenvs/owod/lib/python3.11/site-packages/django/db/backends/utils.py", line 80, in _execute_with_wrappers
    return executor(sql, params, many, context)
           ^^^^^^^^^^^^^^^^^^^^^^^^^^^^^^^^^^^^
  File "/home/zaffarelli/.virtualenvs/owod/lib/python3.11/site-packages/django/db/backends/utils.py", line 84, in _execute
    with self.db.wrap_database_errors:
  File "/home/zaffarelli/.virtualenvs/owod/lib/python3.11/site-packages/django/db/utils.py", line 91, in __exit__
    raise dj_exc_value.with_traceback(traceback) from exc_value
  File "/home/zaffarelli/.virtualenvs/owod/lib/python3.11/site-packages/django/db/backends/utils.py", line 89, in _execute
    return self.cursor.execute(sql, params)
           ^^^^^^^^^^^^^^^^^^^^^^^^^^^^^^^^
  File "/home/zaffarelli/.virtualenvs/owod/lib/python3.11/site-packages/django/db/backends/mysql/base.py", line 75, in execute
    return self.cursor.execute(query, args)
           ^^^^^^^^^^^^^^^^^^^^^^^^^^^^^^^^
  File "/home/zaffarelli/.virtualenvs/owod/lib64/python3.11/site-packages/MySQLdb/cursors.py", line 206, in execute
    res = self._query(query)
          ^^^^^^^^^^^^^^^^^^
  File "/home/zaffarelli/.virtualenvs/owod/lib64/python3.11/site-packages/MySQLdb/cursors.py", line 319, in _query
    db.query(q)
  File "/home/zaffarelli/.virtualenvs/owod/lib64/python3.11/site-packages/MySQLdb/connections.py", line 254, in query
    _mysql.connection.query(self, query)
django.db.utils.DataError: (1264, "Out of range value for column 'trueage' at row 1")
[12/06 22:40:00] "GET /ajax/display/gaia_wheel/ HTTP/1.1" 500 311715
[12/06 22:40:12] Internal Server Error: /ajax/display/gaia_wheel/
Traceback (most recent call last):
  File "/home/zaffarelli/.virtualenvs/owod/lib/python3.11/site-packages/django/db/backends/utils.py", line 89, in _execute
    return self.cursor.execute(sql, params)
           ^^^^^^^^^^^^^^^^^^^^^^^^^^^^^^^^
  File "/home/zaffarelli/.virtualenvs/owod/lib/python3.11/site-packages/django/db/backends/mysql/base.py", line 75, in execute
    return self.cursor.execute(query, args)
           ^^^^^^^^^^^^^^^^^^^^^^^^^^^^^^^^
  File "/home/zaffarelli/.virtualenvs/owod/lib64/python3.11/site-packages/MySQLdb/cursors.py", line 206, in execute
    res = self._query(query)
          ^^^^^^^^^^^^^^^^^^
  File "/home/zaffarelli/.virtualenvs/owod/lib64/python3.11/site-packages/MySQLdb/cursors.py", line 319, in _query
    db.query(q)
  File "/home/zaffarelli/.virtualenvs/owod/lib64/python3.11/site-packages/MySQLdb/connections.py", line 254, in query
    _mysql.connection.query(self, query)
MySQLdb.DataError: (1264, "Out of range value for column 'trueage' at row 1")

The above exception was the direct cause of the following exception:

Traceback (most recent call last):
  File "/home/zaffarelli/.virtualenvs/owod/lib/python3.11/site-packages/django/core/handlers/exception.py", line 55, in inner
    response = get_response(request)
               ^^^^^^^^^^^^^^^^^^^^^
  File "/home/zaffarelli/.virtualenvs/owod/lib/python3.11/site-packages/django/core/handlers/base.py", line 197, in _get_response
    response = wrapped_callback(request, *callback_args, **callback_kwargs)
               ^^^^^^^^^^^^^^^^^^^^^^^^^^^^^^^^^^^^^^^^^^^^^^^^^^^^^^^^^^^^
  File "/home/zaffarelli/Perso/github/wawwod/collector/views/base.py", line 287, in display_gaia_wheel
    gaia_wheel_context = {'data': build_gaia_wheel()}
                                  ^^^^^^^^^^^^^^^^^^
  File "/home/zaffarelli/Perso/github/wawwod/collector/utils/data_collection.py", line 311, in build_gaia_wheel
    creature.save()
  File "/home/zaffarelli/.virtualenvs/owod/lib/python3.11/site-packages/django/db/models/base.py", line 814, in save
    self.save_base(
  File "/home/zaffarelli/.virtualenvs/owod/lib/python3.11/site-packages/django/db/models/base.py", line 877, in save_base
    updated = self._save_table(
              ^^^^^^^^^^^^^^^^^
  File "/home/zaffarelli/.virtualenvs/owod/lib/python3.11/site-packages/django/db/models/base.py", line 990, in _save_table
    updated = self._do_update(
              ^^^^^^^^^^^^^^^^
  File "/home/zaffarelli/.virtualenvs/owod/lib/python3.11/site-packages/django/db/models/base.py", line 1054, in _do_update
    return filtered._update(values) > 0
           ^^^^^^^^^^^^^^^^^^^^^^^^
  File "/home/zaffarelli/.virtualenvs/owod/lib/python3.11/site-packages/django/db/models/query.py", line 1231, in _update
    return query.get_compiler(self.db).execute_sql(CURSOR)
           ^^^^^^^^^^^^^^^^^^^^^^^^^^^^^^^^^^^^^^^^^^^^^^^
  File "/home/zaffarelli/.virtualenvs/owod/lib/python3.11/site-packages/django/db/models/sql/compiler.py", line 1982, in execute_sql
    cursor = super().execute_sql(result_type)
             ^^^^^^^^^^^^^^^^^^^^^^^^^^^^^^^^
  File "/home/zaffarelli/.virtualenvs/owod/lib/python3.11/site-packages/django/db/models/sql/compiler.py", line 1560, in execute_sql
    cursor.execute(sql, params)
  File "/home/zaffarelli/.virtualenvs/owod/lib/python3.11/site-packages/django/db/backends/utils.py", line 102, in execute
    return super().execute(sql, params)
           ^^^^^^^^^^^^^^^^^^^^^^^^^^^^
  File "/home/zaffarelli/.virtualenvs/owod/lib/python3.11/site-packages/django/db/backends/utils.py", line 67, in execute
    return self._execute_with_wrappers(
           ^^^^^^^^^^^^^^^^^^^^^^^^^^^^
  File "/home/zaffarelli/.virtualenvs/owod/lib/python3.11/site-packages/django/db/backends/utils.py", line 80, in _execute_with_wrappers
    return executor(sql, params, many, context)
           ^^^^^^^^^^^^^^^^^^^^^^^^^^^^^^^^^^^^
  File "/home/zaffarelli/.virtualenvs/owod/lib/python3.11/site-packages/django/db/backends/utils.py", line 84, in _execute
    with self.db.wrap_database_errors:
  File "/home/zaffarelli/.virtualenvs/owod/lib/python3.11/site-packages/django/db/utils.py", line 91, in __exit__
    raise dj_exc_value.with_traceback(traceback) from exc_value
  File "/home/zaffarelli/.virtualenvs/owod/lib/python3.11/site-packages/django/db/backends/utils.py", line 89, in _execute
    return self.cursor.execute(sql, params)
           ^^^^^^^^^^^^^^^^^^^^^^^^^^^^^^^^
  File "/home/zaffarelli/.virtualenvs/owod/lib/python3.11/site-packages/django/db/backends/mysql/base.py", line 75, in execute
    return self.cursor.execute(query, args)
           ^^^^^^^^^^^^^^^^^^^^^^^^^^^^^^^^
  File "/home/zaffarelli/.virtualenvs/owod/lib64/python3.11/site-packages/MySQLdb/cursors.py", line 206, in execute
    res = self._query(query)
          ^^^^^^^^^^^^^^^^^^
  File "/home/zaffarelli/.virtualenvs/owod/lib64/python3.11/site-packages/MySQLdb/cursors.py", line 319, in _query
    db.query(q)
  File "/home/zaffarelli/.virtualenvs/owod/lib64/python3.11/site-packages/MySQLdb/connections.py", line 254, in query
    _mysql.connection.query(self, query)
django.db.utils.DataError: (1264, "Out of range value for column 'trueage' at row 1")
[12/06 22:40:12] "GET /ajax/display/gaia_wheel/ HTTP/1.1" 500 311715
[12/06 22:45:13] "GET /static/collector/clans/blood_brothers.webp HTTP/1.1" 404 1861
[12/06 22:45:13] "GET /static/collector/clans/gargoyle.webp HTTP/1.1" 404 1843
[12/06 22:46:15] Internal Server Error: /ajax/display/gaia_wheel/
Traceback (most recent call last):
  File "/home/zaffarelli/.virtualenvs/owod/lib/python3.11/site-packages/django/db/backends/utils.py", line 89, in _execute
    return self.cursor.execute(sql, params)
           ^^^^^^^^^^^^^^^^^^^^^^^^^^^^^^^^
  File "/home/zaffarelli/.virtualenvs/owod/lib/python3.11/site-packages/django/db/backends/mysql/base.py", line 75, in execute
    return self.cursor.execute(query, args)
           ^^^^^^^^^^^^^^^^^^^^^^^^^^^^^^^^
  File "/home/zaffarelli/.virtualenvs/owod/lib64/python3.11/site-packages/MySQLdb/cursors.py", line 206, in execute
    res = self._query(query)
          ^^^^^^^^^^^^^^^^^^
  File "/home/zaffarelli/.virtualenvs/owod/lib64/python3.11/site-packages/MySQLdb/cursors.py", line 319, in _query
    db.query(q)
  File "/home/zaffarelli/.virtualenvs/owod/lib64/python3.11/site-packages/MySQLdb/connections.py", line 254, in query
    _mysql.connection.query(self, query)
MySQLdb.DataError: (1264, "Out of range value for column 'trueage' at row 1")

The above exception was the direct cause of the following exception:

Traceback (most recent call last):
  File "/home/zaffarelli/.virtualenvs/owod/lib/python3.11/site-packages/django/core/handlers/exception.py", line 55, in inner
    response = get_response(request)
               ^^^^^^^^^^^^^^^^^^^^^
  File "/home/zaffarelli/.virtualenvs/owod/lib/python3.11/site-packages/django/core/handlers/base.py", line 197, in _get_response
    response = wrapped_callback(request, *callback_args, **callback_kwargs)
               ^^^^^^^^^^^^^^^^^^^^^^^^^^^^^^^^^^^^^^^^^^^^^^^^^^^^^^^^^^^^
  File "/home/zaffarelli/Perso/github/wawwod/collector/views/base.py", line 287, in display_gaia_wheel
    gaia_wheel_context = {'data': build_gaia_wheel()}
                                  ^^^^^^^^^^^^^^^^^^
  File "/home/zaffarelli/Perso/github/wawwod/collector/utils/data_collection.py", line 311, in build_gaia_wheel
    creature.save()
  File "/home/zaffarelli/.virtualenvs/owod/lib/python3.11/site-packages/django/db/models/base.py", line 814, in save
    self.save_base(
  File "/home/zaffarelli/.virtualenvs/owod/lib/python3.11/site-packages/django/db/models/base.py", line 877, in save_base
    updated = self._save_table(
              ^^^^^^^^^^^^^^^^^
  File "/home/zaffarelli/.virtualenvs/owod/lib/python3.11/site-packages/django/db/models/base.py", line 990, in _save_table
    updated = self._do_update(
              ^^^^^^^^^^^^^^^^
  File "/home/zaffarelli/.virtualenvs/owod/lib/python3.11/site-packages/django/db/models/base.py", line 1054, in _do_update
    return filtered._update(values) > 0
           ^^^^^^^^^^^^^^^^^^^^^^^^
  File "/home/zaffarelli/.virtualenvs/owod/lib/python3.11/site-packages/django/db/models/query.py", line 1231, in _update
    return query.get_compiler(self.db).execute_sql(CURSOR)
           ^^^^^^^^^^^^^^^^^^^^^^^^^^^^^^^^^^^^^^^^^^^^^^^
  File "/home/zaffarelli/.virtualenvs/owod/lib/python3.11/site-packages/django/db/models/sql/compiler.py", line 1982, in execute_sql
    cursor = super().execute_sql(result_type)
             ^^^^^^^^^^^^^^^^^^^^^^^^^^^^^^^^
  File "/home/zaffarelli/.virtualenvs/owod/lib/python3.11/site-packages/django/db/models/sql/compiler.py", line 1560, in execute_sql
    cursor.execute(sql, params)
  File "/home/zaffarelli/.virtualenvs/owod/lib/python3.11/site-packages/django/db/backends/utils.py", line 102, in execute
    return super().execute(sql, params)
           ^^^^^^^^^^^^^^^^^^^^^^^^^^^^
  File "/home/zaffarelli/.virtualenvs/owod/lib/python3.11/site-packages/django/db/backends/utils.py", line 67, in execute
    return self._execute_with_wrappers(
           ^^^^^^^^^^^^^^^^^^^^^^^^^^^^
  File "/home/zaffarelli/.virtualenvs/owod/lib/python3.11/site-packages/django/db/backends/utils.py", line 80, in _execute_with_wrappers
    return executor(sql, params, many, context)
           ^^^^^^^^^^^^^^^^^^^^^^^^^^^^^^^^^^^^
  File "/home/zaffarelli/.virtualenvs/owod/lib/python3.11/site-packages/django/db/backends/utils.py", line 84, in _execute
    with self.db.wrap_database_errors:
  File "/home/zaffarelli/.virtualenvs/owod/lib/python3.11/site-packages/django/db/utils.py", line 91, in __exit__
    raise dj_exc_value.with_traceback(traceback) from exc_value
  File "/home/zaffarelli/.virtualenvs/owod/lib/python3.11/site-packages/django/db/backends/utils.py", line 89, in _execute
    return self.cursor.execute(sql, params)
           ^^^^^^^^^^^^^^^^^^^^^^^^^^^^^^^^
  File "/home/zaffarelli/.virtualenvs/owod/lib/python3.11/site-packages/django/db/backends/mysql/base.py", line 75, in execute
    return self.cursor.execute(query, args)
           ^^^^^^^^^^^^^^^^^^^^^^^^^^^^^^^^
  File "/home/zaffarelli/.virtualenvs/owod/lib64/python3.11/site-packages/MySQLdb/cursors.py", line 206, in execute
    res = self._query(query)
          ^^^^^^^^^^^^^^^^^^
  File "/home/zaffarelli/.virtualenvs/owod/lib64/python3.11/site-packages/MySQLdb/cursors.py", line 319, in _query
    db.query(q)
  File "/home/zaffarelli/.virtualenvs/owod/lib64/python3.11/site-packages/MySQLdb/connections.py", line 254, in query
    _mysql.connection.query(self, query)
django.db.utils.DataError: (1264, "Out of range value for column 'trueage' at row 1")
[12/06 22:46:15] "GET /ajax/display/gaia_wheel/ HTTP/1.1" 500 311719
[12/06 22:46:38] "GET /static/collector/clans/gargoyle.webp HTTP/1.1" 404 1843
[12/06 22:46:38] "GET /static/collector/clans/blood_brothers.webp HTTP/1.1" 404 1861
[12/06 22:47:10] "GET /static/collector/clans/gargoyle.webp HTTP/1.1" 404 1843
[12/06 22:47:10] "GET /static/collector/clans/blood_brothers.webp HTTP/1.1" 404 1861
[12/06 22:47:21] "GET /static/collector/clans/blood_brothers.webp HTTP/1.1" 404 1861
[12/06 22:47:21] "GET /static/collector/clans/gargoyle.webp HTTP/1.1" 404 1843
[12/06 22:51:40] "GET /static/collector/clans/blood_brothers.webp HTTP/1.1" 404 1861
[12/06 22:51:40] "GET /static/collector/clans/gargoyle.webp HTTP/1.1" 404 1843
[12/06 22:54:04] Not Found: /favicon.ico
[12/06 22:54:34] Internal Server Error: /admin/collector/creature/
Traceback (most recent call last):
  File "/home/zaffarelli/.virtualenvs/owod/lib/python3.11/site-packages/django/core/handlers/exception.py", line 55, in inner
    response = get_response(request)
               ^^^^^^^^^^^^^^^^^^^^^
  File "/home/zaffarelli/.virtualenvs/owod/lib/python3.11/site-packages/django/core/handlers/base.py", line 197, in _get_response
    response = wrapped_callback(request, *callback_args, **callback_kwargs)
               ^^^^^^^^^^^^^^^^^^^^^^^^^^^^^^^^^^^^^^^^^^^^^^^^^^^^^^^^^^^^
  File "/home/zaffarelli/.virtualenvs/owod/lib/python3.11/site-packages/django/contrib/admin/options.py", line 688, in wrapper
    return self.admin_site.admin_view(view)(*args, **kwargs)
           ^^^^^^^^^^^^^^^^^^^^^^^^^^^^^^^^^^^^^^^^^^^^^^^^^
  File "/home/zaffarelli/.virtualenvs/owod/lib/python3.11/site-packages/django/utils/decorators.py", line 134, in _wrapper_view
    response = view_func(request, *args, **kwargs)
               ^^^^^^^^^^^^^^^^^^^^^^^^^^^^^^^^^^^
  File "/home/zaffarelli/.virtualenvs/owod/lib/python3.11/site-packages/django/views/decorators/cache.py", line 62, in _wrapper_view_func
    response = view_func(request, *args, **kwargs)
               ^^^^^^^^^^^^^^^^^^^^^^^^^^^^^^^^^^^
  File "/home/zaffarelli/.virtualenvs/owod/lib/python3.11/site-packages/django/contrib/admin/sites.py", line 242, in inner
    return view(request, *args, **kwargs)
           ^^^^^^^^^^^^^^^^^^^^^^^^^^^^^^
  File "/home/zaffarelli/.virtualenvs/owod/lib/python3.11/site-packages/django/utils/decorators.py", line 46, in _wrapper
    return bound_method(*args, **kwargs)
           ^^^^^^^^^^^^^^^^^^^^^^^^^^^^^
  File "/home/zaffarelli/.virtualenvs/owod/lib/python3.11/site-packages/django/utils/decorators.py", line 134, in _wrapper_view
    response = view_func(request, *args, **kwargs)
               ^^^^^^^^^^^^^^^^^^^^^^^^^^^^^^^^^^^
  File "/home/zaffarelli/.virtualenvs/owod/lib/python3.11/site-packages/django/contrib/admin/options.py", line 2019, in changelist_view
    self.save_model(request, obj, form, change=True)
  File "/home/zaffarelli/.virtualenvs/owod/lib/python3.11/site-packages/django/contrib/admin/options.py", line 1227, in save_model
    obj.save()
  File "/home/zaffarelli/.virtualenvs/owod/lib/python3.11/site-packages/django/db/models/base.py", line 814, in save
    self.save_base(
  File "/home/zaffarelli/.virtualenvs/owod/lib/python3.11/site-packages/django/db/models/base.py", line 861, in save_base
    pre_save.send(
  File "/home/zaffarelli/.virtualenvs/owod/lib/python3.11/site-packages/django/dispatch/dispatcher.py", line 176, in send
    return [
           ^
  File "/home/zaffarelli/.virtualenvs/owod/lib/python3.11/site-packages/django/dispatch/dispatcher.py", line 177, in <listcomp>
    (receiver, receiver(signal=self, sender=sender, **named))
               ^^^^^^^^^^^^^^^^^^^^^^^^^^^^^^^^^^^^^^^^^^^^^
  File "/home/zaffarelli/Perso/github/wawwod/collector/signals/creatures.py", line 18, in update_creature
    instance.fix()
  File "/home/zaffarelli/Perso/github/wawwod/collector/models/creatures.py", line 698, in fix
    self.fix_ghoul()
  File "/home/zaffarelli/Perso/github/wawwod/collector/models/creatures.py", line 491, in fix_ghoul
    domitor = Creature.objects.get(rid=self.sire)
              ^^^^^^^^^^^^^^^^^^^^^^^^^^^^^^^^^^^
  File "/home/zaffarelli/.virtualenvs/owod/lib/python3.11/site-packages/django/db/models/manager.py", line 87, in manager_method
    return getattr(self.get_queryset(), name)(*args, **kwargs)
           ^^^^^^^^^^^^^^^^^^^^^^^^^^^^^^^^^^^^^^^^^^^^^^^^^^^
  File "/home/zaffarelli/.virtualenvs/owod/lib/python3.11/site-packages/django/db/models/query.py", line 637, in get
    raise self.model.DoesNotExist(
collector.models.creatures.Creature.DoesNotExist: Creature matching query does not exist.
[12/06 22:54:34] "POST /admin/collector/creature/?o=14.-3.1&q= HTTP/1.1" 500 256504
[12/06 22:58:34] "GET /static/collector/clans/gargoyle.webp HTTP/1.1" 404 1843
[12/06 22:58:34] "GET /static/collector/clans/blood_brothers.webp HTTP/1.1" 404 1861
[12/06 23:00:01] "GET /static/collector/clans/blood_brothers.webp HTTP/1.1" 404 1861
[12/06 23:00:01] "GET /static/collector/clans/gargoyle.webp HTTP/1.1" 404 1843
[12/06 23:00:25] "GET /static/collector/clans/blood_brothers.webp HTTP/1.1" 404 1861
[12/06 23:00:25] "GET /static/collector/clans/gargoyle.webp HTTP/1.1" 404 1843
[12/06 23:01:12] "GET /static/collector/clans/blood_brothers.webp HTTP/1.1" 404 1861
[12/06 23:01:12] "GET /static/collector/clans/gargoyle.webp HTTP/1.1" 404 1843
[12/06 23:03:18] "GET /static/collector/clans/gargoyle.webp HTTP/1.1" 404 1843
[12/06 23:03:18] "GET /static/collector/clans/blood_brothers.webp HTTP/1.1" 404 1861
[13/06 13:12:17] Not Found: /ajax/collector_action/refix_all//
[13/06 13:12:17] "GET /ajax/collector_action/refix_all// HTTP/1.1" 404 8753
[13/06 13:13:19] Not Found: /ajax/collector_action/refix_all//
[13/06 13:13:19] "GET /ajax/collector_action/refix_all// HTTP/1.1" 404 8952
[13/06 13:14:07] Not Found: /ajax/collector_action/refix_all//
[13/06 13:14:07] "GET /ajax/collector_action/refix_all// HTTP/1.1" 404 8972
[13/06 13:15:39] Not Found: /ajax/collector_action/refix_all//
[13/06 13:15:39] "GET /ajax/collector_action/refix_all// HTTP/1.1" 404 8972
[13/06 13:17:12] Internal Server Error: /ajax/collector_action/refix_all/
Traceback (most recent call last):
  File "/home/zaffarelli/.virtualenvs/owod/lib/python3.11/site-packages/django/core/handlers/exception.py", line 55, in inner
    response = get_response(request)
               ^^^^^^^^^^^^^^^^^^^^^
  File "/home/zaffarelli/.virtualenvs/owod/lib/python3.11/site-packages/django/core/handlers/base.py", line 197, in _get_response
    response = wrapped_callback(request, *callback_args, **callback_kwargs)
               ^^^^^^^^^^^^^^^^^^^^^^^^^^^^^^^^^^^^^^^^^^^^^^^^^^^^^^^^^^^^
TypeError: refix_all() missing 1 required positional argument: 'slug'
[13/06 13:17:12] "GET /ajax/collector_action/refix_all/ HTTP/1.1" 500 73113
[13/06 13:18:25] "GET /static/collector/clans/blood_brothers.webp HTTP/1.1" 404 1861
[13/06 13:18:25] "GET /static/collector/clans/gargoyle.webp HTTP/1.1" 404 1843
[13/06 17:19:32] "GET /static/storytelling/fonts/Lato-Regular.ttf HTTP/1.1" 404 1861
[13/06 17:25:21] Not Found: /ajax/display/crossover_sheet/Animalism (3)/
[13/06 17:25:21] "GET /ajax/display/crossover_sheet/Animalism%20(3)/ HTTP/1.1" 404 8984
[13/06 17:25:28] Not Found: /ajax/collector_action/refix_all/Animalism_(3)/
[13/06 17:25:28] "GET /ajax/collector_action/refix_all/Animalism_(3)/ HTTP/1.1" 404 8991
[13/06 17:25:34] "GET /static/collector/clans/blood_brothers.webp HTTP/1.1" 404 1861
[13/06 17:25:34] "GET /static/collector/clans/gargoyle.webp HTTP/1.1" 404 1843
[13/06 22:27:37] Not Found: /ajax/collector_action/refix_all/Animalism_(3)/
[13/06 22:27:37] "GET /ajax/collector_action/refix_all/Animalism_(3)/ HTTP/1.1" 404 8991
[14/06 01:54:18] Not Found: /favicon.ico
[14/06 01:55:57] Not Found: /favicon.ico
[14/06 16:05:02] Not Found: /favicon.ico
[14/06 16:05:59] "GET /static/storytelling/fonts/Lato-Regular.ttf HTTP/1.1" 404 1861
[14/06 16:13:36] Not Found: /ajax/collector_action/refix_all/Protean_(2)/
[14/06 16:13:36] "GET /ajax/collector_action/refix_all/Protean_(2)/ HTTP/1.1" 404 8985
[14/06 16:15:02] Not Found: /ajax/display/crossover_sheet/Protean (2)/
[14/06 16:15:02] "GET /ajax/display/crossover_sheet/Protean%20(2)/ HTTP/1.1" 404 8978
[14/06 16:15:12] Not Found: /ajax/display/crossover_sheet/Protean (2)/
[14/06 16:15:12] "GET /ajax/display/crossover_sheet/Protean%20(2)/ HTTP/1.1" 404 8978
[14/06 16:15:26] Not Found: /ajax/display/crossover_sheet/Protean (2)/
[14/06 16:15:26] "GET /ajax/display/crossover_sheet/Protean%20(2)/ HTTP/1.1" 404 8978
[14/06 21:03:59] "GET /static/storytelling/fonts/Lato-Regular.ttf HTTP/1.1" 404 1861
[15/06 17:04:35] Not Found: /favicon.ico
[15/06 22:00:44] "GET /static/storytelling/fonts/Lato-Regular.ttf HTTP/1.1" 404 1861
[15/06 22:01:18] Not Found: /ajax/display/crossover_sheet/Animalism (2)/
[15/06 22:01:18] "GET /ajax/display/crossover_sheet/Animalism%20(2)/ HTTP/1.1" 404 8984
[15/06 22:02:38] Not Found: /ajax/collector_action/refix_all/Animalism_(2)/
[15/06 22:02:38] "GET /ajax/collector_action/refix_all/Animalism_(2)/ HTTP/1.1" 404 8991
[15/06 22:02:43] Not Found: /ajax/display/crossover_sheet/Animalism (2)/
[15/06 22:02:43] "GET /ajax/display/crossover_sheet/Animalism%20(2)/ HTTP/1.1" 404 8984
[15/06 22:02:53] Not Found: /ajax/display/crossover_sheet/Animalism (2)/
[15/06 22:02:53] "GET /ajax/display/crossover_sheet/Animalism%20(2)/ HTTP/1.1" 404 8984
[15/06 22:03:01] Not Found: /ajax/display/crossover_sheet/Animalism (2)/
[15/06 22:03:01] "GET /ajax/display/crossover_sheet/Animalism%20(2)/ HTTP/1.1" 404 8984
[16/06 00:04:21] Not Found: /favicon.ico
[16/06 02:07:12] Not Found: /favicon.ico
[16/06 02:09:28] Not Found: /favicon.ico
[16/06 13:40:22] Not Found: /favicon.ico
[16/06 13:40:22] "GET /favicon.ico HTTP/1.1" 404 8886
[16/06 13:40:26] Not Found: /favicon.ico
[16/06 13:40:56] Not Found: /favicon.ico
[16/06 13:41:49] Not Found: /ajax/collector_action/refix_all/Anita_Klugzmann/
[16/06 13:41:49] "GET /ajax/collector_action/refix_all/Anita_Klugzmann/ HTTP/1.1" 404 8997
[16/06 13:41:59] "GET /static/storytelling/fonts/Lato-Regular.ttf HTTP/1.1" 404 1861
[16/06 15:57:32] "GET /static/storytelling/fonts/Lato-Regular.ttf HTTP/1.1" 404 1861
[16/06 15:57:36] Not Found: /favicon.ico
[16/06 15:57:36] "GET /favicon.ico HTTP/1.1" 404 8886
[17/06 12:54:22] Not Found: /favicon.ico
[17/06 13:04:16] Not Found: /favicon.ico
[18/06 01:57:41] Not Found: /favicon.ico
[18/06 02:00:21] Not Found: /favicon.ico
